Workbook

Sheet 2022-12-02_BAM
A1: Mandatory | L1: Recommended | M1: Mandatory
A2: Recommended | H2: Fixed terminiology/symbols (according to DIN EN ISO 204: 2022) | L2: Mandatory | M2: Recommended
A3: Not mandatory | L3: Not Mandatory | M3: Not mandatory
B4: Category I - DE | C4: Category I - EN | D4: Category II - DE | E4: Category II - EN | F4: Category III - DE | G4: Category III - EN | H4: ITEM DE | I4: ITEM EN | J4: Symbol | K4: Unit | L4: Ranking
A5: =L5 -> Mandatory | B5: Metadaten | C5: Metadata | D5: Versuchsinfo | E5: Test info | F5: Prüfauftrag | G5: Test order | H5: Versuchsdatum | I5: Test date | L5: Mandatory | M5: =L5 -> Mandatory
A6: =L6 -> Mandatory | B6: Metadaten | C6: Metadata | D6: Versuchsinfo | E6: Test info | F6: Prüfauftrag | G6: Test order | H6: Versuchs-ID | I6: Test ID | L6: Mandatory | M6: =L6 -> Mandatory
A7: =L7 -> Recommended | B7: Metadaten | C7: Metadata | D7: Versuchsinfo | E7: Test info | F7: Prüfauftrag | G7: Test order | H7: Projekt | I7: Project | L7: Recommended | M7: =L7 -> Recommended
A8: =L8 -> Recommended | B8: Metadaten | C8: Metadata | D8: Versuchsinfo | E8: Test info | F8: Prüfauftrag | G8: Test order | H8: Bearbeiter | I8: Operator | L8: Recommended | M8: =L8 -> Recommended
A9: =L9 -> Mandatory | B9: Metadaten | C9: Metadata | D9: Versuchsinfo | E9: Test info | F9: Festgelegte Prüfparameter | G9: Specified test parameters | H9: Prüfnorm | I9: Testing Standard | L9: Mandatory | M9: =L9 -> Mandatory
A10: =L10 -> Mandatory | B10: Metadaten | C10: Metadata | D10: Versuchsinfo | E10: Test info | F10: Festgelegte Prüfparameter | G10: Specified test parameters | H10: festgelegte Prüftemperatur | I10: Specified Temperature | J10: T | K10: ℃ | L10: Mandatory | M10: =L10 -> Mandatory
A11: =L11 -> Mandatory | B11: Metadaten | C11: Metadata | D11: Versuchsinfo | E11: Test info | F11: Festgelegte Prüfparameter | G11: Specified test parameters | H11: Prüfspannung | I11: Initial stress | J11: Ro | K11: MPa | L11: Mandatory | M11: =L11 -> Mandatory
A12: =L12 -> Mandatory | B12: Metadaten | C12: Metadata | D12: Versuchsinfo | E12: Test info | F12: Festgelegte Prüfparameter | G12: Specified test parameters | H12: Versuchsart (unterbrochen/nicht unterbrochen) | I12: Test type (interrupted/not interrupted) | L12: Mandatory | M12: =L12 -> Mandatory
A13: =L13 -> Mandatory | B13: Metadaten | C13: Metadata | D13: Versuchsinfo | E13: Test info | F13: Festgelegte Prüfparameter | G13: Specified test parameters | H13: Versuchsende (Zeitvorgabe/Probenbruch) | I13: End of experiment (time limit/test piece break) | L13: Mandatory | M13: =L13 -> Mandatory
A14: =L14 -> Not Mandatory | B14: Metadaten | C14: Metadata | D14: Versuchsinfo | E14: Test info | F14: Festgelegte Prüfparameter | G14: Specified test parameters | H14: Prüfkraft | I14: Test force | K14: kN | L14: Not Mandatory | M14: =L14 -> Not Mandatory
A15: =L15 -> Mandatory | B15: Metadaten | C15: Metadata | D15: geprüfter Werkstoff | E15: Tested material | F15: Werkstoff und Zustand | G15: Material and state | H15: Werkstoffbezeichnung | I15: Material ID | L15: Mandatory | M15: =L15 -> Mandatory
A16: =L16 -> Recommended | B16: Metadaten | C16: Metadata | D16: geprüfter Werkstoff | E16: Tested material | F16: Werkstoff und Zustand | G16: Material and state | H16: Fertigungsverfahren | I16: Manufacturing process | L16: Recommended | M16: =L16 -> Recommended
A17: =L17 -> Recommended | B17: Metadaten | C17: Metadata | D17: geprüfter Werkstoff | E17: Tested material | F17: Werkstoff und Zustand | G17: Material and state | H17: Wärmebehandlung | I17: Heat treatment | L17: Recommended | M17: =L17 -> Recommended
A18: =L18 -> Mandatory | B18: Metadaten | C18: Metadata | D18: geprüfter Werkstoff | E18: Tested material | F18: Werkstoff und Zustand | G18: Material and state | H18: Einkristallorientierung | I18: Single Crystal Orientation | K18: hkl/Theta,Rho | L18: Mandatory | M18: =L18 -> Mandatory
A19: =L19 -> Mandatory | B19: Metadaten | C19: Metadata | D19: geprüfter Werkstoff | E19: Tested material | F19: Probe | G19: Test piece | H19: Probenbezeichnung | I19: Test piece ID | L19: Mandatory | M19: =L19 -> Mandatory
A20: =L20 -> Mandatory | B20: Metadaten | C20: Metadata | D20: geprüfter Werkstoff | E20: Tested material | F20: Probe | G20: Test piece | H20: Probenform | I20: Type of test piece | L20: Mandatory | M20: =L20 -> Mandatory
A21: =L21 -> Recommended | B21: Metadaten | C21: Metadata | D21: geprüfter Werkstoff | E21: Tested material | F21: Probe | G21: Test piece | H21: Probenzeichnung | I21: Test piece technical drawing | L21: Recommended | M21: =L21 -> Recommended
A22: =L22 -> Recommended | B22: Metadaten | C22: Metadata | D22: geprüfter Werkstoff | E22: Tested material | F22: Probe | G22: Test piece | H22: Entnahmestelle der Probe im Rohling | I22: Location of the sample in the blank | L22: Recommended | M22: =L22 -> Recommended
A23: =L23 -> Mandatory | B23: Metadaten | C23: Metadata | D23: Prüf- und Messmittel | E23: Testing and measuring equipment | F23: Prüfmaschine | G23: Testing machine | H23: Prüfmaschinenbezeichnung | I23: Testing machine ID | L23: Mandatory | M23: =L23 -> Mandatory
A24: =L24 -> Not Mandatory | B24: Metadaten | C24: Metadata | D24: Prüf- und Messmittel | E24: Testing and measuring equipment | F24: Prüfmaschine | G24: Testing machine | H24: max. Prüfkraft | I24: max. applied force | K24: kN | L24: Not Mandatory | M24: =L24 -> Not Mandatory
A25: =L25 -> Not Mandatory | B25: Metadaten | C25: Metadata | D25: Prüf- und Messmittel | E25: Testing and measuring equipment | F25: Prüfmaschine | G25: Testing machine | H25: Datenerfassungsgerät | I25: Data acquisition equipment | L25: Not Mandatory | M25: =L25 -> Not Mandatory
A26: =L26 -> Not Mandatory | B26: Metadaten | C26: Metadata | D26: Prüf- und Messmittel | E26: Testing and measuring equipment | F26: Temperatur-Regelung | G26: Temperature control | H26: Regelung über Thermoelementen an Probe/über Ofen | I26: Control via thermocouples on sample/via furnace) | L26: Not Mandatory | M26: =L26 -> Not Mandatory
A27: =L27 -> Recommended | B27: Metadaten | C27: Metadata | D27: Prüf- und Messmittel | E27: Testing and measuring equipment | F27: Temperatur-Regelung | G27: Temperature control | H27: Thermoelemente: Typ | I27: Thermocouple: type | L27: Recommended | M27: =L27 -> Recommended
A28: =L28 -> Recommended | B28: Metadaten | C28: Metadata | D28: Prüf- und Messmittel | E28: Testing and measuring equipment | F28: Temperatur-Regelung | G28: Temperature control | H28: Thermoelemente: Anzahl | I28: Thermocouple: quantity | L28: Recommended | M28: =L28 -> Recommended
A29: =L29 -> Not Mandatory | B29: Metadaten | C29: Metadata | D29: Prüf- und Messmittel | E29: Testing and measuring equipment | F29: Temperatur-Regelung | G29: Temperature control | H29: Messverstärker | I29: Measurement Amplifier | L29: Not Mandatory | M29: =L29 -> Not Mandatory
A30: =L30 -> Mandatory | B30: Metadaten | C30: Metadata | D30: Prüf- und Messmittel | E30: Testing and measuring equipment | F30: Temperatur-Regelung | G30: Temperature control | H30: Gerätnummer-Thermoelement(e) | I30: Equipment ID - thermocouple(s) | L30: Mandatory | M30: =L30 -> Mandatory
A31: =L31 -> Mandatory | B31: Metadaten | C31: Metadata | D31: Prüf- und Messmittel | E31: Testing and measuring equipment | F31: Temperatur-Regelung | G31: Temperature control | H31: Gerätnummer-Messverstärker | I31: Equipment ID - Measurement Amplifier | L31: Mandatory | M31: =L31 -> Mandatory
A32: =L32 -> Recommended | B32: Metadaten | C32: Metadata | D32: Prüf- und Messmittel | E32: Testing and measuring equipment | F32: Dehnungsmessgerät | G32: Extensometer | H32: Dehnungsmessgerät Modellinfo | I32: Extensometer model information | L32: Recommended | M32: =L32 -> Recommended
A33: =L33 -> Mandatory | B33: Metadaten | C33: Metadata | D33: Prüf- und Messmittel | E33: Testing and measuring equipment | F33: Dehnungsmessgerät | G33: Extensometer | H33: Gerätnummer-Dehnungsmessgerät | I33: Equipment ID - Extensometer | L33: Mandatory | M33: =L33 -> Mandatory
A34: =L34 -> Recommended | B34: Metadaten | C34: Metadata | D34: Prüf- und Messmittel | E34: Testing and measuring equipment | F34: Dehnungsmessgerät | G34: Extensometer | H34: Nennmesslänge | I34: Nominal gauge length | L34: Recommended | M34: =L34 -> Recommended
A35: =L35 -> Recommended | B35: Metadaten | C35: Metadata | D35: Prüf- und Messmittel | E35: Testing and measuring equipment | F35: Dehnungsmessgerät | G35: Extensometer | H35: Dehnungsbereich - Obergrenze | I35: Extension range - Upper limit | K35: % | L35: Recommended | M35: =L35 -> Recommended
A36: =L36 -> Recommended | B36: Metadaten | C36: Metadata | D36: Prüf- und Messmittel | E36: Testing and measuring equipment | F36: Dehnungsmessgerät | G36: Extensometer | H36: Dehnungsbereich - Untergrenze | I36: Extension range - Lower limit | K36: % | L36: Recommended | M36: =L36 -> Recommended
A37: =L37 -> Mandatory | B37: Primärdaten | C37: Primary data | D37: Prüfergebnisse | E37: Test results | F37: Zustand zu Versuchsbeginn | G37: State at test start | H37: min. Probendurchmesser bei RT | I37: Min. test piece diameter at room temperature | K37: mm | L37: Mandatory | M37: =L37 -> Mandatory
A38: =L38 -> Mandatory | B38: Primärdaten | C38: Primary data | D38: Prüfergebnisse | E38: Test results | F38: Zustand zu Versuchsbeginn | G38: State at test start | H38: Anfangsmesslänge | I38: Original gauge length | J38: Lo | K38: mm | L38: Mandatory | M38: =L38 -> Mandatory
A39: =L39 -> Mandatory | B39: Primärdaten | C39: Primary data | D39: Prüfergebnisse | E39: Test results | F39: Zustand zu Versuchsbeginn | G39: State at test start | H39: Bezugslänge zur Berechnung der Dehnung | I39: Reference length for calculation of percentage elongations | J39: Lr (Lo) | K39: mm | L39: Mandatory | M39: =L39 -> Mandatory
A40: =L40 -> Mandatory | B40: Primärdaten | C40: Primary data | D40: Prüfergebnisse | E40: Test results | F40: Zustand zu Versuchsbeginn | G40: State at test start | H40: Extensometer-Messlänge | I40: Extensometer gauge length | J40: Le | K40: mm | L40: Mandatory | M40: =L40 -> Mandatory
...

Sheet 2023-15-05_BAM-RUB
A1: Mandatory | L1: Recommended | M1: Mandatory
A2: Recommended | H2: Fixed terminiology/symbols (according to DIN EN ISO 204: 2022) | L2: Mandatory | M2: Recommended
A3: Not mandatory | L3: Not Mandatory | M3: Not mandatory
B4: Category I - DE | C4: Category I - EN | D4: Category II - DE | E4: Category II - EN | F4: Category III - DE | G4: Category III - EN | H4: ITEM DE | I4: ITEM EN | J4: Symbol | K4: Unit | L4: Ranking
A5: =L5 -> Mandatory | B5: Metadaten | C5: Metadata | D5: Versuchsinfo | E5: Test info | F5: Prüfauftrag | G5: Test order | H5: Versuchsdatum | I5: Test date | L5: Mandatory | M5: =L5 -> Mandatory
A6: =L6 -> Mandatory | B6: Metadaten | C6: Metadata | D6: Versuchsinfo | E6: Test info | F6: Prüfauftrag | G6: Test order | H6: Versuchs-ID | I6: Test ID | L6: Mandatory | M6: =L6 -> Mandatory
A7: =L7 -> Recommended | B7: Metadaten | C7: Metadata | D7: Versuchsinfo | E7: Test info | F7: Prüfauftrag | G7: Test order | H7: Projekt | I7: Project | L7: Recommended | M7: =L7 -> Recommended
A8: =L8 -> Recommended | B8: Metadaten | C8: Metadata | D8: Versuchsinfo | E8: Test info | F8: Prüfauftrag | G8: Test order | H8: Bearbeiter | I8: Operator | L8: Recommended | M8: =L8 -> Recommended
A9: =L9 -> Mandatory | B9: Metadaten | C9: Metadata | D9: Versuchsinfo | E9: Test info | F9: Festgelegte Prüfparameter | G9: Specified test parameters | H9: Prüfnorm | I9: Testing Standard | L9: Mandatory | M9: =L9 -> Mandatory
A10: =L10 -> Mandatory | B10: Metadaten | C10: Metadata | D10: Versuchsinfo | E10: Test info | F10: Festgelegte Prüfparameter | G10: Specified test parameters | H10: festgelegte Prüftemperatur | I10: Specified Temperature | J10: T | K10: ℃ | L10: Mandatory | M10: =L10 -> Mandatory
A11: =L11 -> Mandatory | B11: Metadaten | C11: Metadata | D11: Versuchsinfo | E11: Test info | F11: Festgelegte Prüfparameter | G11: Specified test parameters | H11: Prüfspannung | I11: Initial stress | J11: Ro | K11: MPa | L11: Mandatory | M11: =L11 -> Mandatory
A12: =L12 -> Mandatory | B12: Metadaten | C12: Metadata | D12: Versuchsinfo | E12: Test info | F12: Festgelegte Prüfparameter | G12: Specified test parameters | H12: Versuchsart (unterbrochen/nicht unterbrochen) | I12: Test type (interrupted/not interrupted) | L12: Mandatory | M12: =L12 -> Mandatory
A13: =L13 -> Mandatory | B13: Metadaten | C13: Metadata | D13: Versuchsinfo | E13: Test info | F13: Festgelegte Prüfparameter | G13: Specified test parameters | H13: Versuchsende (Zeitvorgabe/Probenbruch/Dehnungsvorgabe) | I13: End of experiment (time limit/test piece break/extension limit) | L13: Mandatory | M13: =L13 -> Mandatory
A14: =L14 -> Not Mandatory | B14: Metadaten | C14: Metadata | D14: Versuchsinfo | E14: Test info | F14: Festgelegte Prüfparameter | G14: Specified test parameters | H14: Prüfkraft | I14: Test force | K14: kN | L14: Not Mandatory | M14: =L14 -> Not Mandatory
A15: =L15 -> Mandatory | B15: Metadaten | C15: Metadata | D15: geprüfter Werkstoff | E15: Tested material | F15: Werkstoff und Zustand | G15: Material and state | H15: Werkstoffbezeichnung | I15: Material ID | L15: Mandatory | M15: =L15 -> Mandatory
A16: =L16 -> Recommended | B16: Metadaten | C16: Metadata | D16: geprüfter Werkstoff | E16: Tested material | F16: Werkstoff und Zustand | G16: Material and state | H16: Fertigungsverfahren | I16: Manufacturing process | L16: Recommended | M16: =L16 -> Recommended
A17: =L17 -> Recommended | B17: Metadaten | C17: Metadata | D17: geprüfter Werkstoff | E17: Tested material | F17: Werkstoff und Zustand | G17: Material and state | H17: Wärmebehandlung | I17: Heat treatment | L17: Recommended | M17: =L17 -> Recommended
A18: =L18 -> Mandatory | B18: Metadaten | C18: Metadata | D18: geprüfter Werkstoff | E18: Tested material | F18: Werkstoff und Zustand | G18: Material and state | H18: Werkstoffbezeichnung | I18: Material ID | L18: Mandatory | M18: =L18 -> Mandatory
A19: =L19 -> Mandatory | B19: Metadaten | C19: Metadata | D19: geprüfter Werkstoff | E19: Tested material | F19: Werkstoff und Zustand | G19: Material and state | H19: Herstellung: Schmelzen | I19: Manufacturing: Melting | L19: Mandatory | M19: =L19 -> Mandatory
A20: =L20 -> Mandatory | B20: Metadaten | C20: Metadata | D20: geprüfter Werkstoff | E20: Tested material | F20: Werkstoff und Zustand | G20: Material and state | H20: Herstellung: Gießen | I20: Manufacturing: Casting | L20: Mandatory | M20: =L20 -> Mandatory
A21: =L21 -> Mandatory | B21: Metadaten | C21: Metadata | D21: geprüfter Werkstoff | E21: Tested material | F21: Werkstoff und Zustand | G21: Material and state | H21: Herstellung: Umschmelzen | I21: Manufacturing: Remelting | L21: Mandatory | M21: =L21 -> Mandatory
A22: =L22 -> Mandatory | B22: Metadaten | C22: Metadata | D22: geprüfter Werkstoff | E22: Tested material | F22: Werkstoff und Zustand | G22: Material and state | H22: Herstellung: Atmosphäre | I22: Manufacturing: Atmosphere | L22: Mandatory | M22: =L22 -> Mandatory
A23: =L23 -> Mandatory | B23: Metadaten | C23: Metadata | D23: geprüfter Werkstoff | E23: Tested material | F23: Werkstoff und Zustand | G23: Material and state | H23: Herstellung: Ein- oder Polykristall erstarrt | I23: Manufacturing: Single or polycrystal solidified | L23: Mandatory | M23: =L23 -> Mandatory
A24: =L24 -> Mandatory | B24: Metadaten | C24: Metadata | D24: geprüfter Werkstoff | E24: Tested material | F24: Werkstoff und Zustand | G24: Material and state | H24: Herstellung: Thermomechanische Behandlung | I24: Manufacturing: Thermomechanical treatment | L24: Mandatory | M24: =L24 -> Mandatory
A25: =L25 -> Mandatory | B25: Metadaten | C25: Metadata | D25: geprüfter Werkstoff | E25: Tested material | F25: Werkstoff und Zustand | G25: Material and state | H25: Wärmebehandlung: Atmosphäre | I25: Heat treatment: Atmosphere | L25: Mandatory | M25: =L25 -> Mandatory
A26: =L26 -> Mandatory | B26: Metadaten | C26: Metadata | D26: geprüfter Werkstoff | E26: Tested material | F26: Werkstoff und Zustand | G26: Material and state | H26: Wärmebehandlung: Heizrate | I26: Heat treatment: Heating rate | L26: Mandatory | M26: =L26 -> Mandatory
... A54: =L54 -> Mandatory | B54: Metadaten | C54: Metadata | D54: Prüf- und Messmittel | E54: Testing and measuring equipment | F54: Prüfmaschine | G54: Testing machine | H54: Prüfmaschinenbezeichnung | I54: Testing machine ID | L54: Mandatory | M54: =L54 -> Mandatory
A55: =L55 -> Not Mandatory | B55: Metadaten | C55: Metadata | D55: Prüf- und Messmittel | E55: Testing and measuring equipment | F55: Prüfmaschine | G55: Testing machine | H55: max. Prüfkraft | I55: max. applied force | K55: kN | L55: Not Mandatory | M55: =L55 -> Not Mandatory
A56: =L56 -> Not Mandatory | B56: Metadaten | C56: Metadata | D56: Prüf- und Messmittel | E56: Testing and measuring equipment | F56: Prüfmaschine | G56: Testing machine | H56: Datenerfassungsgerät | I56: Data acquisition equipment | L56: Not Mandatory | M56: =L56 -> Not Mandatory
A57: =L57 -> Not Mandatory | B57: Metadaten | C57: Metadata | D57: Prüf- und Messmittel | E57: Testing and measuring equipment | F57: Temperatur-Regelung | G57: Temperature control | H57: Regelung über Thermoelementen an Probe/über Ofen | I57: Control via thermocouples on sample/via furnace) | L57: Not Mandatory | M57: =L57 -> Not Mandatory
A58: =L58 -> Recommended | B58: Metadaten | C58: Metadata | D58: Prüf- und Messmittel | E58: Testing and measuring equipment | F58: Temperatur-Regelung | G58: Temperature control | H58: Thermoelemente: Typ | I58: Thermocouple: type | L58: Recommended | M58: =L58 -> Recommended
A59: =L59 -> Recommended | B59: Metadaten | C59: Metadata | D59: Prüf- und Messmittel | E59: Testing and measuring equipment | F59: Temperatur-Regelung | G59: Temperature control | H59: Thermoelemente: Anzahl | I59: Thermocouple: quantity | L59: Recommended | M59: =L59 -> Recommended
A60: =L60 -> Mandatory | B60: Metadaten | C60: Metadata | D60: Prüf- und Messmittel | E60: Testing and measuring equipment | F60: Temperatur-Regelung | G60: Temperature control | H60: Gerätnummer-Thermoelement(e) | I60: Equipment ID - thermocouple(s) | L60: Mandatory | M60: =L60 -> Mandatory
A61: =L61 -> Not Mandatory | B61: Metadaten | C61: Metadata | D61: Prüf- und Messmittel | E61: Testing and measuring equipment | F61: Temperatur-Regelung | G61: Temperature control | H61: Messverstärker | I61: Measurement Amplifier | L61: Not Mandatory | M61: =L61 -> Not Mandatory
A62: =L62 -> Mandatory | B62: Metadaten | C62: Metadata | D62: Prüf- und Messmittel | E62: Testing and measuring equipment | F62: Temperatur-Regelung | G62: Temperature control | H62: Gerätnummer-Messverstärker | I62: Equipment ID - Measurement Amplifier | L62: Mandatory | M62: =L62 -> Mandatory
A63: =L63 -> Recommended | B63: Metadaten | C63: Metadata | D63: Prüf- und Messmittel | E63: Testing and measuring equipment | F63: Dehnungsmessgerät | G63: Extensometer | H63: Dehnungsmessgerät Modellinfo | I63: Extensometer model information | L63: Recommended | M63: =L63 -> Recommended
A64: =L64 -> Mandatory | B64: Metadaten | C64: Metadata | D64: Prüf- und Messmittel | E64: Testing and measuring equipment | F64: Dehnungsmessgerät | G64: Extensometer | H64: Gerätnummer-Dehnungsmessgerät | I64: Equipment ID - Extensometer | L64: Mandatory | M64: =L64 -> Mandatory
A65: =L65 -> Recommended | B65: Metadaten | C65: Metadata | D65: Prüf- und Messmittel | E65: Testing and measuring equipment | F65: Dehnungsmessgerät | G65: Extensometer | H65: Nennmesslänge | I65: Nominal gauge length | L65: Recommended | M65: =L65 -> Recommended
A66: =L66 -> Recommended | B66: Metadaten | C66: Metadata | D66: Prüf- und Messmittel | E66: Testing and measuring equipment | F66: Dehnungsmessgerät | G66: Extensometer | H66: Dehnungsbereich - Obergrenze | I66: Extension range - Upper limit | K66: % | L66: Recommended | M66: =L66 -> Recommended
A67: =L67 -> Recommended | B67: Metadaten | C67: Metadata | D67: Prüf- und Messmittel | E67: Testing and measuring equipment | F67: Dehnungsmessgerät | G67: Extensometer | H67: Dehnungsbereich - Untergrenze | I67: Extension range - Lower limit | K67: % | L67: Recommended | M67: =L67 -> Recommended
...

Sheet 2023-16-05_BAM-RUB
A1: Mandatory | L1: Recommended | M1: Mandatory
A2: Recommended | D2: necessary? (OMS) | H2: Fixed terminiology/symbols (according to DIN EN ISO 204: 2022) | L2: Mandatory | M2: Recommended
A3: Not mandatory | L3: Not Mandatory | M3: Not mandatory
B4: Category I - DE | C4: Category I - EN | D4: Category II - DE | E4: Category II - EN | F4: Category III - DE | G4: Category III - EN | H4: ITEM DE | I4: ITEM EN | J4: Symbol | K4: Unit | L4: Ranking | N4: Input type (interface) | O4: JSON schema implementation? | P4: Ontology implementation
A5: =L5 -> Mandatory | B5: Metadaten | C5: Metadata | D5: Versuchsinfo | E5: Test info | F5: Prüfauftrag | G5: Test order | H5: Versuchsdatum | I5: Test date | L5: Mandatory | M5: =L5 -> Mandatory
A6: =L6 -> Mandatory | B6: Metadaten | C6: Metadata | D6: Versuchsinfo | E6: Test info | F6: Prüfauftrag | G6: Test order | H6: Versuchs-ID | I6: Test ID | L6: Mandatory | M6: =L6 -> Mandatory
A7: =L7 -> Recommended | B7: Metadaten | C7: Metadata | D7: Versuchsinfo | E7: Test info | F7: Prüfauftrag | G7: Test order | H7: Projekt | I7: Project | L7: Recommended | M7: =L7 -> Recommended
A8: =L8 -> Recommended | B8: Metadaten | C8: Metadata | D8: Versuchsinfo | E8: Test info | F8: Prüfauftrag | G8: Test order | H8: Bearbeiter | I8: Operator | L8: Recommended | M8: =L8 -> Recommended
A9: =L9 -> Mandatory | B9: Metadaten | C9: Metadata | D9: Versuchsinfo | E9: Test info | F9: Festgelegte Prüfparameter | G9: Specified test parameters | H9: Prüfnorm | I9: Testing Standard | L9: Mandatory | M9: =L9 -> Mandatory
A10: =L10 -> Mandatory | B10: Metadaten | C10: Metadata | D10: Versuchsinfo | E10: Test info | F10: Festgelegte Prüfparameter | G10: Specified test parameters | H10: festgelegte Prüftemperatur | I10: Specified Temperature | J10: T | K10: ℃ | L10: Mandatory | M10: =L10 -> Mandatory
A11: =L11 -> Mandatory | B11: Metadaten | C11: Metadata | D11: Versuchsinfo | E11: Test info | F11: Festgelegte Prüfparameter | G11: Specified test parameters | H11: Prüfspannung | I11: Initial stress | J11: Ro | K11: MPa | L11: Mandatory | M11: =L11 -> Mandatory
A12: =L12 -> Mandatory | B12: Metadaten | C12: Metadata | D12: Versuchsinfo | E12: Test info | F12: Festgelegte Prüfparameter | G12: Specified test parameters | H12: Versuchsart (unterbrochen/nicht unterbrochen) | I12: Test type (interrupted/not interrupted) | L12: Mandatory | M12: =L12 -> Mandatory
A13: =L13 -> Mandatory | B13: Metadaten | C13: Metadata | D13: Versuchsinfo | E13: Test info | F13: Festgelegte Prüfparameter | G13: Specified test parameters | H13: Versuchsende (Zeitvorgabe/Probenbruch/Dehnungsvorgabe) | I13: End of experiment (time limit/test piece break/extension limit) | L13: Mandatory | M13: =L13 -> Mandatory
A14: =L14 -> Not Mandatory | B14: Metadaten | C14: Metadata | D14: Versuchsinfo | E14: Test info | F14: Festgelegte Prüfparameter | G14: Specified test parameters | H14: Prüfkraft | I14: Test force | K14: kN | L14: Not Mandatory | M14: =L14 -> Not Mandatory
A15: =L15 -> Mandatory | B15: Metadaten | C15: Metadata | D15: geprüfter Werkstoff | E15: Tested material | F15: Werkstoff und Zustand | G15: Material and state | H15: Werkstoffbezeichnung | I15: Material ID | L15: Mandatory | M15: =L15 -> Mandatory
A16: =L16 -> Recommended | B16: Metadaten | C16: Metadata | D16: geprüfter Werkstoff | E16: Tested material | F16: Werkstoff und Zustand | G16: Material and state | H16: Fertigungsverfahren | I16: Manufacturing process | L16: Recommended | M16: =L16 -> Recommended
A17: =L17 -> Recommended | B17: Metadaten | C17: Metadata | D17: geprüfter Werkstoff | E17: Tested material | F17: Werkstoff und Zustand | G17: Material and state | H17: Wärmebehandlung | I17: Heat treatment | L17: Recommended | M17: =L17 -> Recommended
A18: =L18 -> Mandatory | B18: Metadaten | C18: Metadata | D18: geprüfter Werkstoff | E18: Tested material | F18: Werkstoff und Zustand | G18: Material and state | H18: Werkstoffbezeichnung | I18: Material ID | L18: Mandatory | M18: =L18 -> Mandatory
A19: =L19 -> Mandatory | B19: Metadaten | C19: Metadata | D19: geprüfter Werkstoff | E19: Tested material | F19: Werkstoff und Zustand | G19: Material and state | H19: Herstellung: Schmelzen | I19: Manufacturing: Melting | L19: Mandatory | M19: =L19 -> Mandatory | N19: yes / no + evtl. details
A20: =L20 -> Mandatory | B20: Metadaten | C20: Metadata | D20: geprüfter Werkstoff | E20: Tested material | F20: Werkstoff und Zustand | G20: Material and state | H20: Herstellung: Gießen | I20: Manufacturing: Casting | L20: Mandatory | M20: =L20 -> Mandatory | N20: yes / no + evtl. details
A21: =L21 -> Mandatory | B21: Metadaten | C21: Metadata | D21: geprüfter Werkstoff | E21: Tested material | F21: Werkstoff und Zustand | G21: Material and state | H21: Herstellung: Umschmelzen | I21: Manufacturing: Remelting | L21: Mandatory | M21: =L21 -> Mandatory | N21: yes / no + evtl. details
A22: =L22 -> Mandatory | B22: Metadaten | C22: Metadata | D22: geprüfter Werkstoff | E22: Tested material | F22: Werkstoff und Zustand | G22: Material and state | H22: Herstellung: Atmosphäre | I22: Manufacturing: Atmosphere | L22: Mandatory | M22: =L22 -> Mandatory
A23: =L23 -> Mandatory | B23: Metadaten | C23: Metadata | D23: geprüfter Werkstoff | E23: Tested material | F23: Werkstoff und Zustand | G23: Material and state | H23: Herstellung: Ein- oder Polykristall erstarrt | I23: Manufacturing: Single or polycrystal solidified | L23: Mandatory | M23: =L23 -> Mandatory
A24: =L24 -> Mandatory | B24: Metadaten | C24: Metadata | D24: geprüfter Werkstoff | E24: Tested material | F24: Werkstoff und Zustand | G24: Material and state | H24: Herstellung: Thermomechanische Behandlung | I24: Manufacturing: Thermomechanical treatment | L24: Mandatory | M24: =L24 -> Mandatory | N24: yes / no + evtl. details
B25: Metadaten | C25: Metadata | D25: geprüfter Werkstoff | E25: Tested material | F25: Werkstoffgeschichte und Zustand? | G25: same as condition?(Angelika) | H25: Zustand: wärmebehandelt / wie gefertigt | I25: Condition: Heat treated / as manufactured | L25: Mandatory | N25: drop down list / text
A26: =L26 -> Recommended | B26: Metadaten | C26: Metadata | D26: geprüfter Werkstoff | E26: Tested material | F26: Werkstoff und Zustand | G26: Material and state | H26: Wärmebehandlung: Atmosphäre | I26: Heat treatment: Atmosphere | L26: Recommended | M26: =L26 -> Recommended
A27: =L27 -> Recommended | B27: Metadaten | C27: Metadata | D27: geprüfter Werkstoff | E27: Tested material | F27: Werkstoff und Zustand | G27: Material and state | H27: Wärmebehandlung: Heizrate | I27: Heat treatment: Heating rate | L27: Recommended | M27: =L27 -> Recommended
A28: =L28 -> Recommended | B28: Metadaten | C28: Metadata | D28: geprüfter Werkstoff | E28: Tested material | F28: Werkstoff und Zustand | G28: Material and state | H28: Wärmebehandlung: Temperatur | I28: Heat treatment: Temperature | L28: Recommended | M28: =L28 -> Recommended
A29: =L29 -> Recommended | B29: Metadaten | C29: Metadata | D29: geprüfter Werkstoff | E29: Tested material | F29: Werkstoff und Zustand | G29: Material and state | H29: Wärmebehandlung: Haltezeit | I29: Heat treatment: Soaking time | L29: Recommended | M29: =L29 -> Recommended
A30: =L30 -> Recommended | B30: Metadaten | C30: Metadata | D30: geprüfter Werkstoff | E30: Tested material | F30: Werkstoff und Zustand | G30: Material and state | H30: Wärmebehandlung: Kühlrate | I30: Heat treatment: Cooling rate | L30: Recommended | M30: =L30 -> Recommended
A31: =L31 -> Recommended | B31: Metadaten | C31: Metadata | D31: geprüfter Werkstoff | E31: Tested material | F31: Werkstoff und Zustand | G31: Material and state | H31: Wärmebehandlung: ggf. Angaben zu zweiter Stufe | I31: Heat treatment: Information on second stage, if applicable | L31: Recommended | M31: =L31 -> Recommended
A32: =L32 -> Mandatory | B32: Metadaten | C32: Metadata | D32: geprüfter Werkstoff | E32: Tested material | F32: Werkstoff und Zustand | G32: Material and state | H32: Auslagerung durchgeführt? | I32: Ageing applied? | L32: Mandatory | M32: =L32 -> Mandatory | N32: yes / no
A33: =L33 -> Recommended | B33: Metadaten | C33: Metadata | D33: geprüfter Werkstoff | E33: Tested material | F33: Werkstoff und Zustand | G33: Material and state | H33: Auslagerung: Atmosphäre | I33: Ageing: Atmosphere | L33: Recommended | M33: =L33 -> Recommended
A34: =L34 -> Recommended | B34: Metadaten | C34: Metadata | D34: geprüfter Werkstoff | E34: Tested material | F34: Werkstoff und Zustand | G34: Material and state | H34: Auslagerung: Heizrate | I34: Ageing: Heating rate | L34: Recommended | M34: =L34 -> Recommended
A35: =L35 -> Recommended | B35: Metadaten | C35: Metadata | D35: geprüfter Werkstoff | E35: Tested material | F35: Werkstoff und Zustand | G35: Material and state | H35: Auslagerung: Temperatur | I35: Ageing: Temperature | L35: Recommended | M35: =L35 -> Recommended
A36: =L36 -> Recommended | B36: Metadaten | C36: Metadata | D36: geprüfter Werkstoff | E36: Tested material | F36: Werkstoff und Zustand | G36: Material and state | H36: Auslagerung: Haltezeit | I36: Ageing: Soaking time | L36: Recommended | M36: =L36 -> Recommended
A37: =L37 -> Recommended | B37: Metadaten | C37: Metadata | D37: geprüfter Werkstoff | E37: Tested material | F37: Werkstoff und Zustand | G37: Material and state | H37: Auslagerung: Kühlrate | I37: Ageing: Cooling rate | L37: Recommended | M37: =L37 -> Recommended
A38: =L38 -> Mandatory | B38: Metadaten | C38: Metadata | D38: geprüfter Werkstoff | E38: Tested material | F38: Werkstoff und Zustand | G38: Material and state | H38: Chemische Zusammensetzung | I38: Chemical composition | L38: Mandatory | M38: =L38 -> Mandatory
A39: =L39 -> Mandatory | B39: Metadaten | C39: Metadata | D39: geprüfter Werkstoff | E39: Tested material | F39: Werkstoff und Zustand | G39: Material and state | H39: Geometrie/Abmessungen des Rohlings | I39: Geometry/dimensions of blank | L39: Mandatory | M39: =L39 -> Mandatory
A40: =L40 -> Mandatory | B40: Metadaten | C40: Metadata | D40: geprüfter Werkstoff | E40: Tested material | F40: Werkstoff und Zustand | G40: Material and state | H40: Mikrogefüge: Wärmebehandlungszustand | I40: Microstructure: Heat treatment condition (annealed, hardened, …) | L40: Mandatory | M40: =L40 -> Mandatory | N40: drop down + other
...

Sheet 2023-26-05
G3: new rows | R3: "paused"
L4: Recommended | M4: Mandatory | R4: All tests of data set
C5: necessary? (OMS) | G5: Fixed terminiology/symbols (according to DIN EN ISO 204: 2022) | L5: Mandatory | M5: Recommended | R5: Test specific
K6: Mandatory statement | L6: Not Mandatory | M6: Not mandatory | R6: …?
A7: Category I - DE | B7: Category I - EN | C7: Category II - DE | D7: Category II - EN | E7: Category III - DE | F7: Category III - EN | G7: ITEM DE | H7: ITEM EN | I7: Symbol | J7: Unit | K7: Value | L7: Ranking | N7: Input type (interface) | O7: JSON schema implementation/integration? | P7: Ontology implementation/integration? | Q7: RUB dataset | R7: "Validity Range"
A8: Metadaten | B8: Metadata | C8: Versuchsinfo | D8: Test info | G8: Bibliographische Information | H8: Bibliographic information
A9: Metadaten | B9: Metadata | C9: Versuchsinfo | D9: Test info | E9: Prüfauftrag | F9: Test order | G9: Versuchsdatum | H9: Test date | L9: Mandatory | M9: =L9 -> Mandatory | Q9: --- | R9: Test specific
A10: Metadaten | B10: Metadata | C10: Versuchsinfo | D10: Test info | E10: Prüfauftrag | F10: Test order | G10: Versuchs-ID | H10: Test ID | L10: Mandatory | M10: =L10 -> Mandatory | Q10: --- | R10: Test specific
A11: Metadaten | B11: Metadata | C11: Versuchsinfo | D11: Test info | E11: Prüfauftrag | F11: Test order | G11: Projekt | H11: Project | L11: Recommended | M11: =L11 -> Recommended | Q11: SFB/TR103 | R11: All tests of data set
A12: Metadaten | B12: Metadata | C12: Versuchsinfo | D12: Test info | E12: Prüfauftrag | F12: Test order | G12: Bearbeiter | H12: Operator | L12: Recommended | M12: =L12 -> Recommended | Q12: --- | R12: Test specific
A13: Metadaten | B13: Metadata | C13: Versuchsinfo | D13: Test info | E13: Festgelegte Prüfparameter | F13: Specified test parameters | G13: Prüfnorm | H13: Testing Standard | K13: Yes (which?) / No | L13: Mandatory | M13: =L13 -> Mandatory | Q13: ? | R13: All tests of data set
A14: Metadaten | B14: Metadata | C14: Versuchsinfo | D14: Test info | E14: Festgelegte Prüfparameter | F14: Specified test parameters | G14: festgelegte Prüftemperatur | H14: Specified Temperature | I14: T | J14: ℃ | L14: Mandatory | M14: =L14 -> Mandatory | Q14: xls | R14: Test specific
A15: Metadaten | B15: Metadata | C15: Versuchsinfo | D15: Test info | E15: Festgelegte Prüfparameter | F15: Specified test parameters | G15: Prüfspannung (should we add whether constant force or constant stress?) | H15: Initial stress | I15: Ro | J15: MPa | L15: Mandatory | M15: =L15 -> Mandatory | Q15: ? | R15: Test specific
A16: Metadaten | B16: Metadata | C16: Versuchsinfo | D16: Test info | E16: Festgelegte Prüfparameter | F16: Specified test parameters | G16: Versuchsart (unterbrochen/nicht unterbrochen) | H16: Test type (interrupted/not interrupted) | L16: Mandatory | M16: =L16 -> Mandatory | Q16: paper | R16: Test specific
A17: Metadaten | B17: Metadata | C17: Versuchsinfo | D17: Test info | E17: Festgelegte Prüfparameter | F17: Specified test parameters | G17: Versuchsende (Zeitvorgabe/Probenbruch/Dehnungsvorgabe) | H17: End of experiment (time limit/test piece break/extension limit) | L17: Mandatory | M17: =L17 -> Mandatory | Q17: xls | R17: Test specific
A18: Metadaten | B18: Metadata | C18: Versuchsinfo | D18: Test info | E18: Festgelegte Prüfparameter | F18: Specified test parameters | G18: Prüfkraft | H18: Test force | J18: kN | L18: Not Mandatory | M18: =L18 -> Not Mandatory | Q18: --- | R18: Test specific
A19: Metadaten | B19: Metadata | C19: geprüfter Werkstoff | D19: Tested material | E19: Werkstoff und Zustand | F19: Material and state | G19: Werkstoffbezeichnung | H19: Material ID | L19: Mandatory | M19: =L19 -> Mandatory | Q19: birth cert. | R19: Test specific
A20: Metadaten | B20: Metadata | C20: geprüfter Werkstoff | D20: Tested material | E20: Werkstoff und Zustand | F20: Material and state | G20: Fertigungsverfahren | H20: Manufacturing process | L20: Recommended | M20: =L20 -> Recommended | Q20: ERBO spec | R20: Test specific
A21: Metadaten | B21: Metadata | C21: geprüfter Werkstoff | D21: Tested material | E21: Werkstoff und Zustand | F21: Material and state | G21: Wärmebehandlung | H21: Heat treatment | L21: Recommended | M21: =L21 -> Recommended | Q21: ERBO spec | R21: Test specific
A22: Metadaten | B22: Metadata | C22: geprüfter Werkstoff | D22: Tested material | G22: Bibliographische Information | H22: Bibliographic information
A23: Metadaten | B23: Metadata | C23: geprüfter Werkstoff | D23: Tested material | E23: Werkstoff und Zustand | F23: Material and state | G23: Werkstoffbezeichnung | H23: Material ID | L23: Mandatory | M23: =L23 -> Mandatory | Q23: birth cert.
A24: Metadaten | B24: Metadata | C24: geprüfter Werkstoff | D24: Tested material | E24: Werkstoff und Zustand | F24: Material and state | G24: Herstellung: Schmelzen | H24: Manufacturing: Melting | L24: Mandatory | M24: =L24 -> Mandatory | N24: yes / no + evtl. details | Q24: ERBO spec
A25: Metadaten | B25: Metadata | C25: geprüfter Werkstoff | D25: Tested material | E25: Werkstoff und Zustand | F25: Material and state | G25: Herstellung: Gießen | H25: Manufacturing: Casting | L25: Mandatory | M25: =L25 -> Mandatory | N25: yes / no + evtl. details | Q25: ERBO spec
A26: Metadaten | B26: Metadata | C26: geprüfter Werkstoff | D26: Tested material | E26: Werkstoff und Zustand | F26: Material and state | G26: Herstellung: Umschmelzen | H26: Manufacturing: Remelting | L26: Mandatory | M26: =L26 -> Mandatory | N26: yes / no + evtl. details | Q26: ERBO spec
A27: Metadaten | B27: Metadata | C27: geprüfter Werkstoff | D27: Tested material | E27: Werkstoff und Zustand | F27: Material and state | G27: Herstellung: Atmosphäre | H27: Manufacturing: Atmosphere | L27: Mandatory | M27: =L27 -> Mandatory | Q27: ERBO spec
A28: Metadaten | B28: Metadata | C28: geprüfter Werkstoff | D28: Tested material | E28: Werkstoff und Zustand | F28: Material and state | G28: Herstellung: Ein- oder Polykristall erstarrt | H28: Manufacturing: Single or polycrystal solidified | L28: Mandatory | M28: =L28 -> Mandatory | Q28: ERBO spec
A29: Metadaten | B29: Metadata | C29: geprüfter Werkstoff | D29: Tested material | E29: Werkstoff und Zustand | F29: Material and state | G29: Herstellung: Thermomechanische Behandlung | H29: Manufacturing: Thermomechanical treatment | L29: Mandatory | M29: =L29 -> Mandatory | N29: yes / no + evtl. details | Q29: ERBO spec
A30: Metadaten | B30: Metadata | C30: geprüfter Werkstoff | D30: Tested material | E30: Werkstoffgeschichte und Zustand? | F30: same as condition?(Angelika) | G30: Zustand: wärmebehandelt / wie gefertigt | H30: Condition: Heat treated / as manufactured | L30: Mandatory | M30: =L30 -> Mandatory | N30: drop down list / text | Q30: ERBO spec
A31: Metadaten | B31: Metadata | C31: geprüfter Werkstoff | D31: Tested material | E31: Werkstoff und Zustand | F31: Material and state | G31: Wärmebehandlung: Atmosphäre | H31: Heat treatment: Atmosphere | L31: Mandatory | M31: =L31 -> Mandatory | Q31: ERBO spec
A32: Metadaten | B32: Metadata | C32: geprüfter Werkstoff | D32: Tested material | E32: Werkstoff und Zustand | F32: Material and state | G32: Wärmebehandlung: Heizrate | H32: Heat treatment: Heating rate | L32: Recommended | M32: =L32 -> Recommended | Q32: ERBO spec
A33: Metadaten | B33: Metadata | C33: geprüfter Werkstoff | D33: Tested material | E33: Werkstoff und Zustand | F33: Material and state | G33: Wärmebehandlung: Temperatur | H33: Heat treatment: Temperature | L33: Recommended | M33: =L33 -> Recommended | Q33: ERBO spec
A34: Metadaten | B34: Metadata | C34: geprüfter Werkstoff | D34: Tested material | E34: Werkstoff und Zustand | F34: Material and state | G34: Wärmebehandlung: Haltezeit | H34: Heat treatment: Soaking time | L34: Recommended | M34: =L34 -> Recommended | Q34: ERBO spec
A35: Metadaten | B35: Metadata | C35: geprüfter Werkstoff | D35: Tested material | E35: Werkstoff und Zustand | F35: Material and state | G35: Wärmebehandlung: Kühlrate | H35: Heat treatment: Cooling rate | L35: Recommended | M35: =L35 -> Recommended | Q35: ERBO spec
A36: Metadaten | B36: Metadata | C36: geprüfter Werkstoff | D36: Tested material | E36: Werkstoff und Zustand | F36: Material and state | G36: Wärmebehandlung: ggf. Angaben zu zweiter Stufe | H36: Heat treatment: Information on second stage, if applicable | L36: Recommended | M36: =L36 -> Recommended | Q36: ERBO spec
A37: Metadaten | B37: Metadata | C37: geprüfter Werkstoff | D37: Tested material | E37: Werkstoff und Zustand | F37: Material and state | G37: Auslagerung durchgeführt? | H37: Ageing applied? | L37: Mandatory | M37: =L37 -> Mandatory | N37: yes / no | Q37: ERBO spec
A38: Metadaten | B38: Metadata | C38: geprüfter Werkstoff | D38: Tested material | E38: Werkstoff und Zustand | F38: Material and state | G38: Auslagerung: Atmosphäre | H38: Ageing: Atmosphere | L38: Recommended | M38: =L38 -> Recommended | Q38: ERBO spec
A39: Metadaten | B39: Metadata | C39: geprüfter Werkstoff | D39: Tested material | E39: Werkstoff und Zustand | F39: Material and state | G39: Auslagerung: Heizrate | H39: Ageing: Heating rate | L39: Recommended | M39: =L39 -> Recommended | Q39: ERBO spec
A40: Metadaten | B40: Metadata | C40: geprüfter Werkstoff | D40: Tested material | E40: Werkstoff und Zustand | F40: Material and state | G40: Auslagerung: Temperatur | H40: Ageing: Temperature | L40: Recommended | M40: =L40 -> Recommended | Q40: ERBO spec
A41: Metadaten | B41: Metadata | C41: geprüfter Werkstoff | D41: Tested material | E41: Werkstoff und Zustand | F41: Material and state | G41: Auslagerung: Haltezeit | H41: Ageing: Soaking time | L41: Recommended | M41: =L41 -> Recommended | Q41: ERBO spec
A42: Metadaten | B42: Metadata | C42: geprüfter Werkstoff | D42: Tested material | E42: Werkstoff und Zustand | F42: Material and state | G42: Auslagerung: Kühlrate | H42: Ageing: Cooling rate | L42: Recommended | M42: =L42 -> Recommended | Q42: ERBO spec
...

Sheet Vocabulary-list-EN
A1: ITEM | B1: DESCRIPTION
A2: ='2023-16-05_BAM-RUB'!I5 -> Test date | B2: Specific date on which the creep test started.
A3: ='2023-16-05_BAM-RUB'!I6 -> Test ID | B3: Unique designation (alphanumeric code, name, or other unique designations) assigned to the creep test for identification purposes.
A4: ='2023-16-05_BAM-RUB'!I7 -> Project | B4: Name or designation of the project where the creep test is conducted.
A5: ='2023-16-05_BAM-RUB'!I8 -> Operator | B5: Designation of the individual who performed the test.
A6: ='2023-16-05_BAM-RUB'!I9 -> Testing Standard | B6: Name of the testing standard under which the creep test was conducted, if applicable.
A7: ='2023-16-05_BAM-RUB'!I10 -> Specified Temperature | B7: Target value of the test temperature.
A8: ='2023-16-05_BAM-RUB'!I11 -> Initial stress | B8: Specified stress for the creep test. It is the target value of the stress in the test piece at the beginning of the test, after it has been heated up to the specified temperature. In a creep test conducted unter constant tensile force, it will change over the test's duration, as the specimen deforms.
A9: ='2023-16-05_BAM-RUB'!I12 -> Test type (interrupted/not interrupted) | B9: Indication whether the test was interrupted or not before failure. Interruptions can be done, e.g, to perform complementary investigations or measurements or when the goal is to reach a specified creep extension.
A10: ='2023-16-05_BAM-RUB'!I13 -> End of experiment (time limit/test piece break/extension limit) | B10: Indication about the decision criterion to end the experiment.
A11: ='2023-16-05_BAM-RUB'!I14 -> Test force | B11: In a creep test conducted unter constant tensile force, force that is applied to the test piece at the test temperature. It is determined with the initial stress and the diameter of the test piece.
A12: ='2023-16-05_BAM-RUB'!I15 -> Material ID | B12: Unique designation (alphanumeric code, name, or other unique designations) assigned to the tested material for identification purposes.
A13: ='2023-16-05_BAM-RUB'!I16 -> Manufacturing process
A14: ='2023-16-05_BAM-RUB'!I17 -> Heat treatment
A15: ='2023-16-05_BAM-RUB'!I18 -> Material ID
A16: ='2023-16-05_BAM-RUB'!I19 -> Manufacturing: Melting
A17: ='2023-16-05_BAM-RUB'!I20 -> Manufacturing: Casting
A18: ='2023-16-05_BAM-RUB'!I21 -> Manufacturing: Remelting
A19: ='2023-16-05_BAM-RUB'!I22 -> Manufacturing: Atmosphere
A20: ='2023-16-05_BAM-RUB'!I23 -> Manufacturing: Single or polycrystal solidified
A21: ='2023-16-05_BAM-RUB'!I24 -> Manufacturing: Thermomechanical treatment
A22: ='2023-16-05_BAM-RUB'!I26 -> Heat treatment: Atmosphere
A23: ='2023-16-05_BAM-RUB'!I27 -> Heat treatment: Heating rate
A24: ='2023-16-05_BAM-RUB'!I28 -> Heat treatment: Temperature
A25: ='2023-16-05_BAM-RUB'!I29 -> Heat treatment: Soaking time
A26: ='2023-16-05_BAM-RUB'!I30 -> Heat treatment: Cooling rate
A27: ='2023-16-05_BAM-RUB'!I31 -> Heat treatment: Information on second stage, if applicable
A28: ='2023-16-05_BAM-RUB'!I33 -> Ageing: Atmosphere
A29: ='2023-16-05_BAM-RUB'!I34 -> Ageing: Heating rate
A30: ='2023-16-05_BAM-RUB'!I35 -> Ageing: Temperature
A31: ='2023-16-05_BAM-RUB'!I36 -> Ageing: Soaking time
A32: ='2023-16-05_BAM-RUB'!I37 -> Ageing: Cooling rate
A33: ='2023-16-05_BAM-RUB'!I38 -> Chemical composition
A34: ='2023-16-05_BAM-RUB'!I39 -> Geometry/dimensions of blank
A35: ='2023-16-05_BAM-RUB'!I40 -> Microstructure: Heat treatment condition (annealed, hardened, …)
A36: ='2023-16-05_BAM-RUB'!I41 -> Microstructure: Type of investigation (metallography, …)
A37: ='2023-16-05_BAM-RUB'!I42 -> Microstructure: completely dissolved and re-precipitated gamma-gamma' regions
A38: ='2023-16-05_BAM-RUB'!I45 -> Microstructure: Gamma'-particles', average size
A39: ='2023-16-05_BAM-RUB'!I46 -> Microstructure: Gamma'-particles', maximum size
A40: ='2023-16-05_BAM-RUB'!I47 -> Microstructure: Heat treatment condition
...

Sheet Vocabulary-list-DE
A1: ITEM | B1: DESCRIPTION
A2: ='2023-16-05_BAM-RUB'!H5 -> Versuchsdatum
A3: ='2023-16-05_BAM-RUB'!H6 -> Versuchs-ID
A4: ='2023-16-05_BAM-RUB'!H7 -> Projekt
A5: ='2023-16-05_BAM-RUB'!H8 -> Bearbeiter
A6: ='2023-16-05_BAM-RUB'!H9 -> Prüfnorm
A7: ='2023-16-05_BAM-RUB'!H10 -> festgelegte Prüftemperatur
A8: ='2023-16-05_BAM-RUB'!H11 -> Prüfspannung
A9: ='2023-16-05_BAM-RUB'!H12 -> Versuchsart (unterbrochen/nicht unterbrochen)
A10: ='2023-16-05_BAM-RUB'!H13 -> Versuchsende (Zeitvorgabe/Probenbruch/Dehnungsvorgabe)
A11: ='2023-16-05_BAM-RUB'!H14 -> Prüfkraft
A12: ='2023-16-05_BAM-RUB'!H15 -> Werkstoffbezeichnung
A13: ='2023-16-05_BAM-RUB'!H16 -> Fertigungsverfahren
... A21: ='2023-16-05_BAM-RUB'!H24 -> Herstellung: Thermomechanische Behandlung
A22: ='2023-16-05_BAM-RUB'!H26 -> Wärmebehandlung: Atmosphäre
A23: ='2023-16-05_BAM-RUB'!H27 -> Wärmebehandlung: Heizrate
A24: ='2023-16-05_BAM-RUB'!H28 -> Wärmebehandlung: Temperatur
A25: ='2023-16-05_BAM-RUB'!H29 -> Wärmebehandlung: Haltezeit
A26: ='2023-16-05_BAM-RUB'!H30 -> Wärmebehandlung: Kühlrate
A27: ='2023-16-05_BAM-RUB'!H31 -> Wärmebehandlung: ggf. Angaben zu zweiter Stufe
A28: ='2023-16-05_BAM-RUB'!H33 -> Auslagerung: Atmosphäre
A29: ='2023-16-05_BAM-RUB'!H34 -> Auslagerung: Heizrate
A30: ='2023-16-05_BAM-RUB'!H35 -> Auslagerung: Temperatur
A31: ='2023-16-05_BAM-RUB'!H36 -> Auslagerung: Haltezeit
A32: ='2023-16-05_BAM-RUB'!H37 -> Auslagerung: Kühlrate
A33: ='2023-16-05_BAM-RUB'!H38 -> Chemische Zusammensetzung
A34: ='2023-16-05_BAM-RUB'!H39 -> Geometrie/Abmessungen des Rohlings
A35: ='2023-16-05_BAM-RUB'!H40 -> Mikrogefüge: Wärmebehandlungszustand
A36: ='2023-16-05_BAM-RUB'!H41 -> Mikrogefüge: Durchführung der Prüfung
A37: ='2023-16-05_BAM-RUB'!H42 -> Mikrogefüge: volls. gelöste und wieder ausgeschiedene gamma-gamma'-Bereiche
A38: ='2023-16-05_BAM-RUB'!H45 -> Mikrogefüge: Gamma'-Teilchengröße, durchschnitliche Größe
A39: ='2023-16-05_BAM-RUB'!H46 -> Mikrogefüge: Gamma'-Teilchengröße, maximale Größe
A40: ='2023-16-05_BAM-RUB'!H47 -> Mikrogefüge: Anschmelzungen
A41: ='2023-16-05_BAM-RUB'!H52 -> Nachweis der Einkristallinität
A42: ='2023-16-05_BAM-RUB'!H53 -> Einkristallorientierung
A43: ='2023-16-05_BAM-RUB'!H54 -> Winkelorientierung
A44: ='2023-16-05_BAM-RUB'!H55 -> Angaben zu Rissprüfung
A45: ='2023-16-05_BAM-RUB'!H56 -> Röntgenfilm?
A46: ='2023-16-05_BAM-RUB'!H57 -> Korndefektkarten?
A47: ='2023-16-05_BAM-RUB'!H58 -> Probenbezeichnung
...
