Workbook

Sheet Data-Schema-Creep_v1.1
C1: DATA SCHEMA FOR CREEP DATA OF NI-BASED SUPERALLOYS
C2: DOI: 10.5281/zenodo.11668375
D4: This version of the data schema covers creep tests with the following features: - It considers single- and poly-crystalline specimen material - Terminology is aligned with ISO 204: 2022 - Creep test under tension and constant force - Temperature measurement with thermocouples - Contacting extensometer system Columns B to E are categories that define the overarching structure of the schema. Columns F to H are the single entries with the respective symbol and unit, if applicable. The units are community-common units. Column I is the data type. It should give a first hint on how to answer to each entry field. Column J provides exemplary answers for most of the entries and the options of the related drop-down list, if applicable. Column K is the requirement profile (see text on the right). Column L includes further explanations on the requirement and on the applicability of some entries. | F4: The Requirement Profile (column K) is for the highest quality class of reference datasets which shall enable the following usages: 1. Checking own creep test results on nominally similar material 2. Verification of own testing set-up (e.g. by testing same/similar material) 3. Using the data as input data for simulations of creep behavior for design and alloy development The requirement profile given in column K refers to the highest quality level of reference creep data, taken from calibrated instruments. Other quality classes or typical research datasets require less documentation. Our current definition for reference data of materials is available here: https://doi.org/10.5281/zenodo.11667673
K6: Mandatory
K7: Optional
A8: ROW | B8: CATEGORY I | C8: CATEGORY II | D8: CATEGORY III | E8: CATEGORY IV (Detailed Information) | F8: ENTRY | G8: SYMBOL | H8: UNIT | I8: DATA TYPE | J8: EXEMPLARY ANSWER / OPTIONS (IN CASE OF DROP-DOWN LIST) | K8: REQUIREMENT | L8: COMMENT
A9: 1 | B9: Metadata | C9: Test info | D9: Test job details | F9: Date of test start | I9: Date | J9: 45041 | K9: Mandatory
A10: 2 | B10: Metadata | C10: Test info | D10: Test job details | F10: Data of test end | I10: Date | J10: 45061.5 | K10: Mandatory
A11: 3 | B11: Metadata | C11: Test info | D11: Test job details | F11: Test ID | I11: Alphanumeric | J11: Vh5205-C-99 | K11: Mandatory
A12: 4 | B12: Metadata | C12: Test info | D12: Test job details | F12: Project | I12: Alphanumeric | J12: NFDI-MatWerk | K12: Optional
A13: 5 | B13: Metadata | C13: Test info | D13: Test job details | F13: Test order | I13: Alphanumeric | K13: Optional
A14: 6 | B14: Metadata | C14: Test info | D14: Test parameters | F14: Was the test performed according to a test standard? | I14: Drop-down list | J14: Yes / No | K14: Mandatory | L14: "Yes" is mandatory
A15: 7 | B15: Metadata | C15: Test info | D15: Test parameters | F15: Test standard | I15: Alphanumeric | J15: ISO 204 / ASTM E139 | K15: Mandatory | L15: Applicable if test performed according to a test standard (row 6)
A16: 8 | B16: Metadata | C16: Test info | D16: Test parameters | F16: Specified temperature | G16: T | H16: ℃ | I16: Numeric | J16: 980 | K16: Mandatory
A17: 9 | B17: Metadata | C17: Test info | D17: Test parameters | F17: Type of loading | I17: Drop-down list | J17: Tension / Compression / Bending | K17: Mandatory
A18: 10 | B18: Metadata | C18: Test info | D18: Test parameters | F18: Load control type | I18: Drop-down list | J18: Constant force / Constant stress | K18: Mandatory
A19: 11 | B19: Metadata | C19: Test info | D19: Test parameters | F19: Initial stress | G19: Ro | H19: MPa | I19: Numeric | J19: 170 | K19: Mandatory
A20: 12 | B20: Metadata | C20: Test info | D20: Test parameters | F20: Test type | I20: Drop-down list | J20: Uninterrupted creep tests with continuous monitoring of extension / Interrupted creep tests with periodic measurement of elongation / Stress rupture tests where normally only the time to fracture is measured | K20: Mandatory
A21: 13 | B21: Metadata | C21: Test info | D21: Test parameters | F21: End of test criterium | I21: Drop-down list | J21: Test piece break / Time limit / Extension limit | K21: Mandatory
A22: 14 | B22: Metadata | C22: Test info | D22: Test parameters | F22: End of test criterium - value (if not test piece break) | I22: Numeric | K22: Mandatory
A23: 15 | B23: Metadata | C23: Test info | D23: Test parameters | F23: Interruption course | I23: Drop-down list | J23: Unloading before cooling / Unloading after cooling | K23: Mandatory
A24: 16 | B24: Metadata | C24: Test info | D24: Test parameters | F24: Test force | H24: kN | I24: Numeric | J24: 5.1 | K24: Optional
A25: 17 | B25: Metadata | C25: Test info | D25: Test parameters | F25: Preload (Part of the test force) | H25: kN | I25: Numeric | J25: 0.2 | K25: Mandatory
A26: 18 | B26: Metadata | C26: Test info | D26: Test parameters | F26: Other additional information (e.g. if constant stress) | I26: Text | K26: Optional
A27: 19 | B27: Metadata | C27: Test info | D27: Related research outcome | F27: Related article(s) available? | I27: Drop-down list | J27: Yes / No | K27: Optional
A28: 20 | B28: Metadata | C28: Test info | D28: Related research outcome | F28: DOI Article 1 | I28: Alphanumeric / Link | J28: https://doi.org/10.1080/09603409.2016.1186414 | K28: Optional
A29: 21 | B29: Metadata | C29: Test info | D29: Related research outcome | F29: Short description of content article 1 | I29: Text | J29: Creep data as published | K29: Optional
A30: 22 | B30: Metadata | C30: Test info | D30: Related research outcome | F30: DOI Article 2 | I30: Alphanumeric / Link | J30: https://doi.org/10.1002/adem.201400136 | K30: Optional
A31: 23 | B31: Metadata | C31: Test info | D31: Related research outcome | F31: Short description of content article 2 | I31: Text | J31: Description of alloy composition, heat treatment and initial microstructure | K31: Optional
A32: 24 | B32: Metadata | C32: Test info | D32: Related research outcome | F32: DOI Article n | I32: Alphanumeric / Link | K32: Optional
A33: 25 | B33: Metadata | C33: Test info | D33: Related research outcome | F33: Short description of content article n | I33: Text | K33: Optional
A34: 26 | B34: Metadata | C34: Material related | D34: History and condition of the material | F34: (Digital) Material Identifier | I34: Alphanumeric | J34: NIMONIC 75 / 2.4630 / CMSX-6 / CMSX-4 / ERBO1 / … | K34: Mandatory
A35: 27 | B35: Metadata | C35: Material related | D35: History and condition of the material | E35: As-manufactured material | F35: Information on phase equilibrium | I35: Text / (Link to) File, preferably with machine-readable (meta)data | J35: Link to a TTT-curve | K35: Optional
A36: 28 | B36: Metadata | C36: Material related | D36: History and condition of the material | E36: As-manufactured material | F36: Type of as-manufactured material (Cast / Ingot / Extrusion rod / …) | I36: Text | J36: Cast / Ingot / Extrusion rod | K36: Mandatory
A37: 29 | B37: Metadata | C37: Material related | D37: History and condition of the material | E37: As-manufactured material | F37: Description of the as-manufactured material (geometry and dimensions) | I37: Alphanumeric / (Link to) Image or technical drawing | J37: Plate (140 mm x 100 mm x 20 mm) / (link to) image or technical drawing | K37: Mandatory
A38: 30 | B38: Metadata | C38: Material related | D38: History and condition of the material | E38: As-manufactured material | F38: Description of the manufacturing process - as-manufactured material | I38: Text | J38: Cast / Melting, Casting, and Remelting / Induction melting in air, casting into a circular ingot and then electroslag remelting | K38: Optional
A39: 31 | B39: Metadata | C39: Material related | D39: History and condition of the material | E39: As-manufactured material | F39: Casting temperature | H39: °C | I39: Numeric | K39: Optional
A40: 32 | B40: Metadata | C40: Material related | D40: History and condition of the material | E40: As-manufactured material | F40: Casting speed | I40: Numeric | K40: Optional
A41: 33 | B41: Metadata | C41: Material related | D41: History and condition of the material | E41: As-manufactured material | F41: Single or polycrystal solidified | I41: Drop-down list | J41: Single crystal / Polycrystal | K41: Mandatory
A42: 34 | B42: Metadata | C42: Material related | D42: History and condition of the material | E42: As-manufactured material | F42: Condition | I42: Drop-down list | J42: Heat treated / As manufactured | K42: Mandatory
...

Sheet Vh5205_C-85
F1: Mandatory
F2: Optional
A3: ROW | B3: CATEGORIZATION | C3: ENTRY | D3: SYMBOL | E3: UNIT | F3: REQUIREMENT | H3: * Information common to all tests
A4: 1 | B4: Test info-->Test job details--> | C4: Date of test start | F4: Mandatory | G4: 45264.381 | J4: =EXACT(G4,'Vh5205_C-89'!G4) -> FALSE
A5: 2 | B5: Test info-->Test job details--> | C5: Data of test end | F5: Mandatory | G5: 45307.298 | J5: =EXACT(G5,'Vh5205_C-89'!G5) -> FALSE
A6: 3 | B6: Test info-->Test job details--> | C6: Test ID | F6: Mandatory | G6: Vh5205_C-85 | J6: =EXACT(G6,'Vh5205_C-89'!G6) -> FALSE
A7: 4 | B7: Test info-->Test job details--> | C7: Project | F7: Optional | G7: Vh 5205 | H7: * | J7: =EXACT(G7,'Vh5205_C-89'!G7) -> TRUE
A8: 5 | B8: Test info-->Test job details--> | C8: Test order | F8: Optional | G8: Not applicable | H8: * | J8: =EXACT(G8,'Vh5205_C-89'!G8) -> TRUE
A9: 6 | B9: Test info-->Test parameters--> | C9: Was the test performed according to a test standard? | F9: Mandatory | G9: Yes | H9: * | J9: =EXACT(G9,'Vh5205_C-89'!G9) -> TRUE
A10: 7 | B10: Test info-->Test parameters--> | C10: Test standard | F10: Mandatory | G10: DIN EN ISO 204:2019-4 | H10: * | J10: =EXACT(G10,'Vh5205_C-89'!G10) -> TRUE
A11: 8 | B11: Test info-->Test parameters--> | C11: Specified temperature | D11: T | E11: °C | F11: Mandatory | G11: 980 °C | H11: * | J11: =EXACT(G11,'Vh5205_C-89'!G11) -> TRUE
A12: 9 | B12: Test info-->Test parameters--> | C12: Type of loading | F12: Mandatory | G12: Tension | H12: * | J12: =EXACT(G12,'Vh5205_C-89'!G12) -> TRUE
A13: 10 | B13: Test info-->Test parameters--> | C13: Load control type | F13: Mandatory | G13: Constant force | H13: * | J13: =EXACT(G13,'Vh5205_C-89'!G13) -> TRUE
A14: 11 | B14: Test info-->Test parameters--> | C14: Initial stress | D14: Ro | E14: MPa | F14: Mandatory | G14: 140 | J14: =EXACT(G14,'Vh5205_C-89'!G14) -> FALSE
A15: 12 | B15: Test info-->Test parameters--> | C15: Test type | F15: Mandatory | G15: Uninterrupted creep tests with continuous monitoring of extension | H15: * | J15: =EXACT(G15,'Vh5205_C-89'!G15) -> TRUE
A16: 13 | B16: Test info-->Test parameters--> | C16: End of test criterium | F16: Mandatory | G16: Time limit | J16: =EXACT(G16,'Vh5205_C-89'!G16) -> FALSE
A17: 14 | B17: Test info-->Test parameters--> | C17: End of test criterium - value (if not test piece break) | F17: Mandatory | G17: > 1000 h | J17: =EXACT(G17,'Vh5205_C-89'!G17) -> FALSE
A18: 15 | B18: Test info-->Test parameters--> | C18: Interruption course | F18: Mandatory | G18: Unloading after cooling | J18: =EXACT(G18,'Vh5205_C-89'!G18) -> FALSE
A19: 16 | B19: Test info-->Test parameters--> | C19: Test force | E19: kN | F19: Optional | J19: =EXACT(G19,'Vh5205_C-89'!G19) -> TRUE
A20: 17 | B20: Test info-->Test parameters--> | C20: Preload (Part of the test force) | E20: kN | F20: Mandatory | G20: 0,2 kN (20.4 kg) | H20: * | J20: =EXACT(G20,'Vh5205_C-89'!G20) -> TRUE
A21: 18 | B21: Test info-->Test parameters--> | C21: Other additional information (e.g. if constant stress) | F21: Optional | J21: =EXACT(G21,'Vh5205_C-89'!G21) -> TRUE
A22: 19 | B22: Test info-->Related research outcome--> | C22: Related article(s) available? | F22: Optional | G22: No | H22: * | J22: =EXACT(G22,'Vh5205_C-89'!G22) -> TRUE
A23: 20 | B23: Test info-->Related research outcome--> | C23: DOI Article 1 | F23: Optional | J23: =EXACT(G23,'Vh5205_C-89'!G23) -> TRUE
A24: 21 | B24: Test info-->Related research outcome--> | C24: Short description of content article 1 | F24: Optional | J24: =EXACT(G24,'Vh5205_C-89'!G24) -> TRUE
A25: 22 | B25: Test info-->Related research outcome--> | C25: DOI Article 2 | F25: Optional | J25: =EXACT(G25,'Vh5205_C-89'!G25) -> TRUE
A26: 23 | B26: Test info-->Related research outcome--> | C26: Short description of content article 2 | F26: Optional | J26: =EXACT(G26,'Vh5205_C-89'!G26) -> TRUE
A27: 24 | B27: Test info-->Related research outcome--> | C27: DOI Article n | F27: Optional | J27: =EXACT(G27,'Vh5205_C-89'!G27) -> TRUE
A28: 25 | B28: Test info-->Related research outcome--> | C28: Short description of content article n | F28: Optional | J28: =EXACT(G28,'Vh5205_C-89'!G28) -> TRUE
A29: 26 | B29: Material related-->History and condition of the material--> | C29: (Digital) Material Identifier | F29: Mandatory | G29: CMSX-6 | H29: * | J29: =EXACT(G29,'Vh5205_C-89'!G29) -> TRUE
A30: 27 | B30: Material related-->History and condition of the material-->As-manufactured material--> | C30: Information on phase equilibrium | F30: Optional | J30: =EXACT(G30,'Vh5205_C-89'!G30) -> TRUE
A31: 28 | B31: Material related-->History and condition of the material-->As-manufactured material--> | C31: Type of as-manufactured material (Cast / Ingot / Extrusion rod / …) | F31: Mandatory | G31: Ingot | H31: * | J31: =EXACT(G31,'Vh5205_C-89'!G31) -> TRUE
A32: 29 | B32: Material related-->History and condition of the material-->As-manufactured material--> | C32: Description of the as-manufactured material (geometry and dimensions) | F32: Mandatory | G32: Ingot with 4" Diameter | H32: * | J32: =EXACT(G32,'Vh5205_C-89'!G32) -> TRUE
A33: 30 | B33: Material related-->History and condition of the material-->As-manufactured material--> | C33: Description of the manufacturing process - as-manufactured material | F33: Optional | G33: Vacuum Induction Refined | H33: * | J33: =EXACT(G33,'Vh5205_C-89'!G33) -> TRUE
A34: 31 | B34: Material related-->History and condition of the material-->As-manufactured material--> | C34: Casting temperature | E34: °C | F34: Optional | J34: =EXACT(G34,'Vh5205_C-89'!G34) -> TRUE
A35: 32 | B35: Material related-->History and condition of the material-->As-manufactured material--> | C35: Casting speed | F35: Optional | J35: =EXACT(G35,'Vh5205_C-89'!G35) -> TRUE
A36: 33 | B36: Material related-->History and condition of the material-->As-manufactured material--> | C36: Single or polycrystal solidified | F36: Mandatory | G36: Single Crystal | H36: * | J36: =EXACT(G36,'Vh5205_C-89'!G36) -> TRUE
A37: 34 | B37: Material related-->History and condition of the material-->As-manufactured material--> | C37: Condition | F37: Mandatory | G37: Heat Treated | H37: * | J37: =EXACT(G37,'Vh5205_C-89'!G37) -> TRUE
A38: 35 | B38: Material related-->History and condition of the material-->As-tested material--> | C38: Supplier | F38: Mandatory | G38: PCC Airfoils, Inc. Minerva, Ohio. | H38: * | J38: =EXACT(G38,'Vh5205_C-89'!G38) -> TRUE
A39: 36 | B39: Material related-->History and condition of the material-->As-tested material--> | C39: Description of the as-tested material (geometry and dimensions) - The test piece is manufactured from the tested material. | F39: Mandatory | G39: Single Crystal Investment Cast See image file "Test-piece-location.pdf" For details see DOI: 10.7449/1980/Superalloys_1980_205_214, and DOI: 10.7449/1984/Superalloys_1984_167_176 | H39: * | J39: =EXACT(G39,'Vh5205_C-89'!G39) -> TRUE
A40: 37 | B40: Material related-->History and condition of the material-->As-tested material--> | C40: Description of the manufacturing process - as-tested material | F40: Mandatory | G40: Single Crystal Investment Casting from a Vacuum Induction Refined Ingot and subsequent Heat Treatment (annealed and aged). | H40: * | J40: =EXACT(G40,'Vh5205_C-89'!G40) -> TRUE
...

Sheet Vh5205_C-94
F1: Mandatory
F2: Optional
A3: ROW | B3: CATEGORIZATION | C3: ENTRY | D3: SYMBOL | E3: UNIT | F3: REQUIREMENT | H3: * Information common to all tests
A4: 1 | B4: Test info-->Test job details--> | C4: Date of test start | F4: Mandatory | G4: 45217.385 | J4: =EXACT(G4,'Vh5205_C-85'!G4) -> FALSE
A5: 2 | B5: Test info-->Test job details--> | C5: Data of test end | F5: Mandatory | G5: 45259.51 | J5: =EXACT(G5,'Vh5205_C-85'!G5) -> FALSE
A6: 3 | B6: Test info-->Test job details--> | C6: Test ID | F6: Mandatory | G6: Vh5205_C-94 | J6: =EXACT(G6,'Vh5205_C-85'!G6) -> FALSE
A7: 4 | B7: Test info-->Test job details--> | C7: Project | F7: Optional | G7: Vh 5205 | H7: * | J7: =EXACT(G7,'Vh5205_C-85'!G7) -> TRUE
A8: 5 | B8: Test info-->Test job details--> | C8: Test order | F8: Optional | G8: Not applicable | H8: * | J8: =EXACT(G8,'Vh5205_C-85'!G8) -> TRUE
A9: 6 | B9: Test info-->Test parameters--> | C9: Was the test performed according to a test standard? | F9: Mandatory | G9: Yes | H9: * | J9: =EXACT(G9,'Vh5205_C-85'!G9) -> TRUE
A10: 7 | B10: Test info-->Test parameters--> | C10: Test standard | F10: Mandatory | G10: DIN EN ISO 204:2019-4 | H10: * | J10: =EXACT(G10,'Vh5205_C-85'!G10) -> TRUE
A11: 8 | B11: Test info-->Test parameters--> | C11: Specified temperature | D11: T | E11: °C | F11: Mandatory | G11: 980 °C | H11: * | J11: =EXACT(G11,'Vh5205_C-85'!G11) -> TRUE
A12: 9 | B12: Test info-->Test parameters--> | C12: Type of loading | F12: Mandatory | G12: Tension | H12: * | J12: =EXACT(G12,'Vh5205_C-85'!G12) -> TRUE
A13: 10 | B13: Test info-->Test parameters--> | C13: Load control type | F13: Mandatory | G13: Constant force | H13: * | J13: =EXACT(G13,'Vh5205_C-85'!G13) -> TRUE
A14: 11 | B14: Test info-->Test parameters--> | C14: Initial stress | D14: Ro | E14: MPa | F14: Mandatory | G14: 140 | J14: =EXACT(G14,'Vh5205_C-85'!G14) -> TRUE
A15: 12 | B15: Test info-->Test parameters--> | C15: Test type | F15: Mandatory | G15: Uninterrupted creep tests with continuous monitoring of extension | H15: * | J15: =EXACT(G15,'Vh5205_C-85'!G15) -> TRUE
A16: 13 | B16: Test info-->Test parameters--> | C16: End of test criterium | F16: Mandatory | G16: Time limit | J16: =EXACT(G16,'Vh5205_C-85'!G16) -> TRUE
A17: 14 | B17: Test info-->Test parameters--> | C17: End of test criterium - value (if not test piece break) | F17: Mandatory | G17: > 1000 h | J17: =EXACT(G17,'Vh5205_C-85'!G17) -> TRUE
A18: 15 | B18: Test info-->Test parameters--> | C18: Interruption course | F18: Mandatory | G18: Unloading after cooling | J18: =EXACT(G18,'Vh5205_C-85'!G18) -> TRUE
A19: 16 | B19: Test info-->Test parameters--> | C19: Test force | E19: kN | F19: Optional | J19: =EXACT(G19,'Vh5205_C-85'!G19) -> TRUE
A20: 17 | B20: Test info-->Test parameters--> | C20: Preload (Part of the test force) | E20: kN | F20: Mandatory | G20: 0,2 kN (20.4 kg) | H20: * | J20: =EXACT(G20,'Vh5205_C-85'!G20) -> TRUE
A21: 18 | B21: Test info-->Test parameters--> | C21: Other additional information (e.g. if constant stress) | F21: Optional | J21: =EXACT(G21,'Vh5205_C-85'!G21) -> TRUE
A22: 19 | B22: Test info-->Related research outcome--> | C22: Related article(s) available? | F22: Optional | G22: No | H22: * | J22: =EXACT(G22,'Vh5205_C-85'!G22) -> TRUE
A23: 20 | B23: Test info-->Related research outcome--> | C23: DOI Article 1 | F23: Optional | J23: =EXACT(G23,'Vh5205_C-85'!G23) -> TRUE
A24: 21 | B24: Test info-->Related research outcome--> | C24: Short description of content article 1 | F24: Optional | J24: =EXACT(G24,'Vh5205_C-85'!G24) -> TRUE
A25: 22 | B25: Test info-->Related research outcome--> | C25: DOI Article 2 | F25: Optional | J25: =EXACT(G25,'Vh5205_C-85'!G25) -> TRUE
A26: 23 | B26: Test info-->Related research outcome--> | C26: Short description of content article 2 | F26: Optional | J26: =EXACT(G26,'Vh5205_C-85'!G26) -> TRUE
A27: 24 | B27: Test info-->Related research outcome--> | C27: DOI Article n | F27: Optional | J27: =EXACT(G27,'Vh5205_C-85'!G27) -> TRUE
A28: 25 | B28: Test info-->Related research outcome--> | C28: Short description of content article n | F28: Optional | J28: =EXACT(G28,'Vh5205_C-85'!G28) -> TRUE
A29: 26 | B29: Material related-->History and condition of the material--> | C29: (Digital) Material Identifier | F29: Mandatory | G29: CMSX-6 | H29: * | J29: =EXACT(G29,'Vh5205_C-85'!G29) -> TRUE
A30: 27 | B30: Material related-->History and condition of the material-->As-manufactured material--> | C30: Information on phase equilibrium | F30: Optional | J30: =EXACT(G30,'Vh5205_C-85'!G30) -> TRUE
A31: 28 | B31: Material related-->History and condition of the material-->As-manufactured material--> | C31: Type of as-manufactured material (Cast / Ingot / Extrusion rod / …) | F31: Mandatory | G31: Ingot | H31: * | J31: =EXACT(G31,'Vh5205_C-85'!G31) -> TRUE
A32: 29 | B32: Material related-->History and condition of the material-->As-manufactured material--> | C32: Description of the as-manufactured material (geometry and dimensions) | F32: Mandatory | G32: Ingot with 4" Diameter | H32: * | J32: =EXACT(G32,'Vh5205_C-85'!G32) -> TRUE
A33: 30 | B33: Material related-->History and condition of the material-->As-manufactured material--> | C33: Description of the manufacturing process - as-manufactured material | F33: Optional | G33: Vacuum Induction Refined | H33: * | J33: =EXACT(G33,'Vh5205_C-85'!G33) -> TRUE
A34: 31 | B34: Material related-->History and condition of the material-->As-manufactured material--> | C34: Casting temperature | E34: °C | F34: Optional | J34: =EXACT(G34,'Vh5205_C-85'!G34) -> TRUE
A35: 32 | B35: Material related-->History and condition of the material-->As-manufactured material--> | C35: Casting speed | F35: Optional | J35: =EXACT(G35,'Vh5205_C-85'!G35) -> TRUE
A36: 33 | B36: Material related-->History and condition of the material-->As-manufactured material--> | C36: Single or polycrystal solidified | F36: Mandatory | G36: Single Crystal | H36: * | J36: =EXACT(G36,'Vh5205_C-85'!G36) -> TRUE
A37: 34 | B37: Material related-->History and condition of the material-->As-manufactured material--> | C37: Condition | F37: Mandatory | G37: Heat Treated | H37: * | J37: =EXACT(G37,'Vh5205_C-85'!G37) -> TRUE
A38: 35 | B38: Material related-->History and condition of the material-->As-tested material--> | C38: Supplier | F38: Mandatory | G38: PCC Airfoils, Inc. Minerva, Ohio. | H38: * | J38: =EXACT(G38,'Vh5205_C-85'!G38) -> TRUE
A39: 36 | B39: Material related-->History and condition of the material-->As-tested material--> | C39: Description of the as-tested material (geometry and dimensions) - The test piece is manufactured from the tested material. | F39: Mandatory | G39: Single Crystal Investment Cast See image file "Test-piece-location.pdf" For details see DOI: 10.7449/1980/Superalloys_1980_205_214, and DOI: 10.7449/1984/Superalloys_1984_167_176 | H39: * | J39: =EXACT(G39,'Vh5205_C-85'!G39) -> TRUE
A40: 37 | B40: Material related-->History and condition of the material-->As-tested material--> | C40: Description of the manufacturing process - as-tested material | F40: Mandatory | G40: Single Crystal Investment Casting from a Vacuum Induction Refined Ingot and subsequent Heat Treatment (annealed and aged). | H40: * | J40: =EXACT(G40,'Vh5205_C-85'!G40) -> TRUE
...

Sheet Vh5205_C-95
F1: Mandatory
F2: Optional
A3: ROW | B3: CATEGORIZATION | C3: ENTRY | D3: SYMBOL | E3: UNIT | F3: REQUIREMENT | H3: * Information common to all tests
A4: 1 | B4: Test info-->Test job details--> | C4: Date of test start | F4: Mandatory | G4: 45168.379 | J4: =EXACT(G4,'Vh5205_C-94'!G4) -> FALSE
A5: 2 | B5: Test info-->Test job details--> | C5: Data of test end | F5: Mandatory | G5: 45210.463 | J5: =EXACT(G5,'Vh5205_C-94'!G5) -> FALSE
A6: 3 | B6: Test info-->Test job details--> | C6: Test ID | F6: Mandatory | G6: Vh5205_C-95 | J6: =EXACT(G6,'Vh5205_C-94'!G6) -> FALSE
A7: 4 | B7: Test info-->Test job details--> | C7: Project | F7: Optional | G7: Vh 5205 | H7: * | J7: =EXACT(G7,'Vh5205_C-94'!G7) -> TRUE
A8: 5 | B8: Test info-->Test job details--> | C8: Test order | F8: Optional | G8: Not applicable | H8: * | J8: =EXACT(G8,'Vh5205_C-94'!G8) -> TRUE
A9: 6 | B9: Test info-->Test parameters--> | C9: Was the test performed according to a test standard? | F9: Mandatory | G9: Yes | H9: * | J9: =EXACT(G9,'Vh5205_C-94'!G9) -> TRUE
A10: 7 | B10: Test info-->Test parameters--> | C10: Test standard | F10: Mandatory | G10: DIN EN ISO 204:2019-4 | H10: * | J10: =EXACT(G10,'Vh5205_C-94'!G10) -> TRUE
A11: 8 | B11: Test info-->Test parameters--> | C11: Specified temperature | D11: T | E11: °C | F11: Mandatory | G11: 980 °C | H11: * | J11: =EXACT(G11,'Vh5205_C-94'!G11) -> TRUE
A12: 9 | B12: Test info-->Test parameters--> | C12: Type of loading | F12: Mandatory | G12: Tension | H12: * | J12: =EXACT(G12,'Vh5205_C-94'!G12) -> TRUE
A13: 10 | B13: Test info-->Test parameters--> | C13: Load control type | F13: Mandatory | G13: Constant force | H13: * | J13: =EXACT(G13,'Vh5205_C-94'!G13) -> TRUE
A14: 11 | B14: Test info-->Test parameters--> | C14: Initial stress | D14: Ro | E14: MPa | F14: Mandatory | G14: 140 | J14: =EXACT(G14,'Vh5205_C-94'!G14) -> TRUE
A15: 12 | B15: Test info-->Test parameters--> | C15: Test type | F15: Mandatory | G15: Uninterrupted creep tests with continuous monitoring of extension | H15: * | J15: =EXACT(G15,'Vh5205_C-94'!G15) -> TRUE
A16: 13 | B16: Test info-->Test parameters--> | C16: End of test criterium | F16: Mandatory | G16: Time limit | J16: =EXACT(G16,'Vh5205_C-94'!G16) -> TRUE
A17: 14 | B17: Test info-->Test parameters--> | C17: End of test criterium - value (if not test piece break) | F17: Mandatory | G17: > 1000 h | J17: =EXACT(G17,'Vh5205_C-94'!G17) -> TRUE
A18: 15 | B18: Test info-->Test parameters--> | C18: Interruption course | F18: Mandatory | G18: Unloading after cooling | J18: =EXACT(G18,'Vh5205_C-94'!G18) -> TRUE
A19: 16 | B19: Test info-->Test parameters--> | C19: Test force | E19: kN | F19: Optional | J19: =EXACT(G19,'Vh5205_C-94'!G19) -> TRUE
A20: 17 | B20: Test info-->Test parameters--> | C20: Preload (Part of the test force) | E20: kN | F20: Mandatory | G20: 0,2 kN (20.4 kg) | H20: * | J20: =EXACT(G20,'Vh5205_C-94'!G20) -> TRUE
A21: 18 | B21: Test info-->Test parameters--> | C21: Other additional information (e.g. if constant stress) | F21: Optional | J21: =EXACT(G21,'Vh5205_C-94'!G21) -> TRUE
A22: 19 | B22: Test info-->Related research outcome--> | C22: Related article(s) available? | F22: Optional | G22: No | H22: * | J22: =EXACT(G22,'Vh5205_C-94'!G22) -> TRUE
A23: 20 | B23: Test info-->Related research outcome--> | C23: DOI Article 1 | F23: Optional | J23: =EXACT(G23,'Vh5205_C-94'!G23) -> TRUE
A24: 21 | B24: Test info-->Related research outcome--> | C24: Short description of content article 1 | F24: Optional | J24: =EXACT(G24,'Vh5205_C-94'!G24) -> TRUE
A25: 22 | B25: Test info-->Related research outcome--> | C25: DOI Article 2 | F25: Optional | J25: =EXACT(G25,'Vh5205_C-94'!G25) -> TRUE
A26: 23 | B26: Test info-->Related research outcome--> | C26: Short description of content article 2 | F26: Optional | J26: =EXACT(G26,'Vh5205_C-94'!G26) -> TRUE
A27: 24 | B27: Test info-->Related research outcome--> | C27: DOI Article n | F27: Optional | J27: =EXACT(G27,'Vh5205_C-94'!G27) -> TRUE
A28: 25 | B28: Test info-->Related research outcome--> | C28: Short description of content article n | F28: Optional | J28: =EXACT(G28,'Vh5205_C-94'!G28) -> TRUE
A29: 26 | B29: Material related-->History and condition of the material--> | C29: (Digital) Material Identifier | F29: Mandatory | G29: CMSX-6 | H29: * | J29: =EXACT(G29,'Vh5205_C-94'!G29) -> TRUE
A30: 27 | B30: Material related-->History and condition of the material-->As-manufactured material--> | C30: Information on phase equilibrium | F30: Optional | J30: =EXACT(G30,'Vh5205_C-94'!G30) -> TRUE
A31: 28 | B31: Material related-->History and condition of the material-->As-manufactured material--> | C31: Type of as-manufactured material (Cast / Ingot / Extrusion rod / …) | F31: Mandatory | G31: Ingot | H31: * | J31: =EXACT(G31,'Vh5205_C-94'!G31) -> TRUE
A32: 29 | B32: Material related-->History and condition of the material-->As-manufactured material--> | C32: Description of the as-manufactured material (geometry and dimensions) | F32: Mandatory | G32: Ingot with 4" Diameter | H32: * | J32: =EXACT(G32,'Vh5205_C-94'!G32) -> TRUE
A33: 30 | B33: Material related-->History and condition of the material-->As-manufactured material--> | C33: Description of the manufacturing process - as-manufactured material | F33: Optional | G33: Vacuum Induction Refined | H33: * | J33: =EXACT(G33,'Vh5205_C-94'!G33) -> TRUE
A34: 31 | B34: Material related-->History and condition of the material-->As-manufactured material--> | C34: Casting temperature | E34: °C | F34: Optional | J34: =EXACT(G34,'Vh5205_C-94'!G34) -> TRUE
A35: 32 | B35: Material related-->History and condition of the material-->As-manufactured material--> | C35: Casting speed | F35: Optional | J35: =EXACT(G35,'Vh5205_C-94'!G35) -> TRUE
A36: 33 | B36: Material related-->History and condition of the material-->As-manufactured material--> | C36: Single or polycrystal solidified | F36: Mandatory | G36: Single Crystal | H36: * | J36: =EXACT(G36,'Vh5205_C-94'!G36) -> TRUE
A37: 34 | B37: Material related-->History and condition of the material-->As-manufactured material--> | C37: Condition | F37: Mandatory | G37: Heat Treated | H37: * | J37: =EXACT(G37,'Vh5205_C-94'!G37) -> TRUE
A38: 35 | B38: Material related-->History and condition of the material-->As-tested material--> | C38: Supplier | F38: Mandatory | G38: PCC Airfoils, Inc. Minerva, Ohio. | H38: * | J38: =EXACT(G38,'Vh5205_C-94'!G38) -> TRUE
A39: 36 | B39: Material related-->History and condition of the material-->As-tested material--> | C39: Description of the as-tested material (geometry and dimensions) - The test piece is manufactured from the tested material. | F39: Mandatory | G39: Single Crystal Investment Cast See image file "Test-piece-location.pdf" For details see DOI: 10.7449/1980/Superalloys_1980_205_214, and DOI: 10.7449/1984/Superalloys_1984_167_176 | H39: * | J39: =EXACT(G39,'Vh5205_C-94'!G39) -> TRUE
A40: 37 | B40: Material related-->History and condition of the material-->As-tested material--> | C40: Description of the manufacturing process - as-tested material | F40: Mandatory | G40: Single Crystal Investment Casting from a Vacuum Induction Refined Ingot and subsequent Heat Treatment (annealed and aged). | H40: * | J40: =EXACT(G40,'Vh5205_C-94'!G40) -> TRUE
...

Sheet Vh5205_C-81
F1: Mandatory
F2: Optional
A3: ROW | B3: CATEGORIZATION | C3: ENTRY | D3: SYMBOL | E3: UNIT | F3: REQUIREMENT | H3: * Information common to all tests
A4: 1 | B4: Test info-->Test job details--> | C4: Date of test start | F4: Mandatory | G4: 45041.383 | J4: =EXACT(G4,'Vh5205_C-95'!G4) -> FALSE
A5: 2 | B5: Test info-->Test job details--> | C5: Data of test end | F5: Mandatory | G5: 45061.842 | J5: =EXACT(G5,'Vh5205_C-95'!G5) -> FALSE
A6: 3 | B6: Test info-->Test job details--> | C6: Test ID | F6: Mandatory | G6: Vh5205_C-81 | J6: =EXACT(G6,'Vh5205_C-95'!G6) -> FALSE
A7: 4 | B7: Test info-->Test job details--> | C7: Project | F7: Optional | G7: Vh 5205 | H7: * | J7: =EXACT(G7,'Vh5205_C-95'!G7) -> TRUE
A8: 5 | B8: Test info-->Test job details--> | C8: Test order | F8: Optional | G8: Not applicable | H8: * | J8: =EXACT(G8,'Vh5205_C-95'!G8) -> TRUE
A9: 6 | B9: Test info-->Test parameters--> | C9: Was the test performed according to a test standard? | F9: Mandatory | G9: Yes | H9: * | J9: =EXACT(G9,'Vh5205_C-95'!G9) -> TRUE
A10: 7 | B10: Test info-->Test parameters--> | C10: Test standard | F10: Mandatory | G10: DIN EN ISO 204:2019-4 | H10: * | J10: =EXACT(G10,'Vh5205_C-95'!G10) -> TRUE
A11: 8 | B11: Test info-->Test parameters--> | C11: Specified temperature | D11: T | E11: °C | F11: Mandatory | G11: 980 °C | H11: * | J11: =EXACT(G11,'Vh5205_C-95'!G11) -> TRUE
A12: 9 | B12: Test info-->Test parameters--> | C12: Type of loading | F12: Mandatory | G12: Tension | H12: * | J12: =EXACT(G12,'Vh5205_C-95'!G12) -> TRUE
A13: 10 | B13: Test info-->Test parameters--> | C13: Load control type | F13: Mandatory | G13: Constant force | H13: * | J13: =EXACT(G13,'Vh5205_C-95'!G13) -> TRUE
A14: 11 | B14: Test info-->Test parameters--> | C14: Initial stress | D14: Ro | E14: MPa | F14: Mandatory | G14: 170 | J14: =EXACT(G14,'Vh5205_C-95'!G14) -> FALSE
A15: 12 | B15: Test info-->Test parameters--> | C15: Test type | F15: Mandatory | G15: Uninterrupted creep tests with continuous monitoring of extension | H15: * | J15: =EXACT(G15,'Vh5205_C-95'!G15) -> TRUE
A16: 13 | B16: Test info-->Test parameters--> | C16: End of test criterium | F16: Mandatory | G16: Test piece break | J16: =EXACT(G16,'Vh5205_C-95'!G16) -> FALSE
A17: 14 | B17: Test info-->Test parameters--> | C17: End of test criterium - value (if not test piece break) | F17: Mandatory | G17: Not applicable | J17: =EXACT(G17,'Vh5205_C-95'!G17) -> FALSE
A18: 15 | B18: Test info-->Test parameters--> | C18: Interruption course | F18: Mandatory | G18: Not applicable | J18: =EXACT(G18,'Vh5205_C-95'!G18) -> FALSE
A19: 16 | B19: Test info-->Test parameters--> | C19: Test force | E19: kN | F19: Optional | J19: =EXACT(G19,'Vh5205_C-95'!G19) -> TRUE
A20: 17 | B20: Test info-->Test parameters--> | C20: Preload (Part of the test force) | E20: kN | F20: Mandatory | G20: 0,2 kN (20.4 kg) | H20: * | J20: =EXACT(G20,'Vh5205_C-95'!G20) -> TRUE
A21: 18 | B21: Test info-->Test parameters--> | C21: Other additional information (e.g. if constant stress) | F21: Optional | J21: =EXACT(G21,'Vh5205_C-95'!G21) -> TRUE
A22: 19 | B22: Test info-->Related research outcome--> | C22: Related article(s) available? | F22: Optional | G22: No | H22: * | J22: =EXACT(G22,'Vh5205_C-95'!G22) -> TRUE
A23: 20 | B23: Test info-->Related research outcome--> | C23: DOI Article 1 | F23: Optional | J23: =EXACT(G23,'Vh5205_C-95'!G23) -> TRUE
A24: 21 | B24: Test info-->Related research outcome--> | C24: Short description of content article 1 | F24: Optional | J24: =EXACT(G24,'Vh5205_C-95'!G24) -> TRUE
A25: 22 | B25: Test info-->Related research outcome--> | C25: DOI Article 2 | F25: Optional | J25: =EXACT(G25,'Vh5205_C-95'!G25) -> TRUE
A26: 23 | B26: Test info-->Related research outcome--> | C26: Short description of content article 2 | F26: Optional | J26: =EXACT(G26,'Vh5205_C-95'!G26) -> TRUE
A27: 24 | B27: Test info-->Related research outcome--> | C27: DOI Article n | F27: Optional | J27: =EXACT(G27,'Vh5205_C-95'!G27) -> TRUE
A28: 25 | B28: Test info-->Related research outcome--> | C28: Short description of content article n | F28: Optional | J28: =EXACT(G28,'Vh5205_C-95'!G28) -> TRUE
A29: 26 | B29: Material related-->History and condition of the material--> | C29: (Digital) Material Identifier | F29: Mandatory | G29: CMSX-6 | H29: * | J29: =EXACT(G29,'Vh5205_C-95'!G29) -> TRUE
A30: 27 | B30: Material related-->History and condition of the material-->As-manufactured material--> | C30: Information on phase equilibrium | F30: Optional | J30: =EXACT(G30,'Vh5205_C-95'!G30) -> TRUE
A31: 28 | B31: Material related-->History and condition of the material-->As-manufactured material--> | C31: Type of as-manufactured material (Cast / Ingot / Extrusion rod / …) | F31: Mandatory | G31: Ingot | H31: * | J31: =EXACT(G31,'Vh5205_C-95'!G31) -> TRUE
A32: 29 | B32: Material related-->History and condition of the material-->As-manufactured material--> | C32: Description of the as-manufactured material (geometry and dimensions) | F32: Mandatory | G32: Ingot with 4" Diameter | H32: * | J32: =EXACT(G32,'Vh5205_C-95'!G32) -> TRUE
A33: 30 | B33: Material related-->History and condition of the material-->As-manufactured material--> | C33: Description of the manufacturing process - as-manufactured material | F33: Optional | G33: Vacuum Induction Refined | H33: * | J33: =EXACT(G33,'Vh5205_C-95'!G33) -> TRUE
A34: 31 | B34: Material related-->History and condition of the material-->As-manufactured material--> | C34: Casting temperature | E34: °C | F34: Optional | J34: =EXACT(G34,'Vh5205_C-95'!G34) -> TRUE
A35: 32 | B35: Material related-->History and condition of the material-->As-manufactured material--> | C35: Casting speed | F35: Optional | J35: =EXACT(G35,'Vh5205_C-95'!G35) -> TRUE
A36: 33 | B36: Material related-->History and condition of the material-->As-manufactured material--> | C36: Single or polycrystal solidified | F36: Mandatory | G36: Single Crystal | H36: * | J36: =EXACT(G36,'Vh5205_C-95'!G36) -> TRUE
A37: 34 | B37: Material related-->History and condition of the material-->As-manufactured material--> | C37: Condition | F37: Mandatory | G37: Heat Treated | H37: * | J37: =EXACT(G37,'Vh5205_C-95'!G37) -> TRUE
A38: 35 | B38: Material related-->History and condition of the material-->As-tested material--> | C38: Supplier | F38: Mandatory | G38: PCC Airfoils, Inc. Minerva, Ohio. | H38: * | J38: =EXACT(G38,'Vh5205_C-95'!G38) -> TRUE
A39: 36 | B39: Material related-->History and condition of the material-->As-tested material--> | C39: Description of the as-tested material (geometry and dimensions) - The test piece is manufactured from the tested material. | F39: Mandatory | G39: Single Crystal Investment Cast See image file "Test-piece-location.pdf" For details see DOI: 10.7449/1980/Superalloys_1980_205_214, and DOI: 10.7449/1984/Superalloys_1984_167_176 | H39: * | J39: =EXACT(G39,'Vh5205_C-95'!G39) -> TRUE
A40: 37 | B40: Material related-->History and condition of the material-->As-tested material--> | C40: Description of the manufacturing process - as-tested material | F40: Mandatory | G40: Single Crystal Investment Casting from a Vacuum Induction Refined Ingot and subsequent Heat Treatment (annealed and aged). | H40: * | J40: =EXACT(G40,'Vh5205_C-95'!G40) -> TRUE
...

Sheet Vh5205_C-91
F1: Mandatory
F2: Optional
A3: ROW | B3: CATEGORIZATION | C3: ENTRY | D3: SYMBOL | E3: UNIT | F3: REQUIREMENT | H3: * Information common to all tests
A4: 1 | B4: Test info-->Test job details--> | C4: Date of test start | F4: Mandatory | G4: 45019.388 | J4: =EXACT(G4,'Vh5205_C-81'!G4) -> FALSE
A5: 2 | B5: Test info-->Test job details--> | C5: Data of test end | F5: Mandatory | G5: 45039.888 | J5: =EXACT(G5,'Vh5205_C-81'!G5) -> FALSE
A6: 3 | B6: Test info-->Test job details--> | C6: Test ID | F6: Mandatory | G6: Vh5205_C-91 | J6: =EXACT(G6,'Vh5205_C-81'!G6) -> FALSE
A7: 4 | B7: Test info-->Test job details--> | C7: Project | F7: Optional | G7: Vh 5205 | H7: * | J7: =EXACT(G7,'Vh5205_C-81'!G7) -> TRUE
A8: 5 | B8: Test info-->Test job details--> | C8: Test order | F8: Optional | G8: Not applicable | H8: * | J8: =EXACT(G8,'Vh5205_C-81'!G8) -> TRUE
A9: 6 | B9: Test info-->Test parameters--> | C9: Was the test performed according to a test standard? | F9: Mandatory | G9: Yes | H9: * | J9: =EXACT(G9,'Vh5205_C-81'!G9) -> TRUE
A10: 7 | B10: Test info-->Test parameters--> | C10: Test standard | F10: Mandatory | G10: DIN EN ISO 204:2019-4 | H10: * | J10: =EXACT(G10,'Vh5205_C-81'!G10) -> TRUE
A11: 8 | B11: Test info-->Test parameters--> | C11: Specified temperature | D11: T | E11: °C | F11: Mandatory | G11: 980 °C | H11: * | J11: =EXACT(G11,'Vh5205_C-81'!G11) -> TRUE
A12: 9 | B12: Test info-->Test parameters--> | C12: Type of loading | F12: Mandatory | G12: Tension | H12: * | J12: =EXACT(G12,'Vh5205_C-81'!G12) -> TRUE
A13: 10 | B13: Test info-->Test parameters--> | C13: Load control type | F13: Mandatory | G13: Constant force | H13: * | J13: =EXACT(G13,'Vh5205_C-81'!G13) -> TRUE
A14: 11 | B14: Test info-->Test parameters--> | C14: Initial stress | D14: Ro | E14: MPa | F14: Mandatory | G14: 170 | J14: =EXACT(G14,'Vh5205_C-81'!G14) -> TRUE
A15: 12 | B15: Test info-->Test parameters--> | C15: Test type | F15: Mandatory | G15: Uninterrupted creep tests with continuous monitoring of extension | H15: * | J15: =EXACT(G15,'Vh5205_C-81'!G15) -> TRUE
A16: 13 | B16: Test info-->Test parameters--> | C16: End of test criterium | F16: Mandatory | G16: Test piece break | J16: =EXACT(G16,'Vh5205_C-81'!G16) -> TRUE
A17: 14 | B17: Test info-->Test parameters--> | C17: End of test criterium - value (if not test piece break) | F17: Mandatory | G17: Not applicable | J17: =EXACT(G17,'Vh5205_C-81'!G17) -> TRUE
A18: 15 | B18: Test info-->Test parameters--> | C18: Interruption course | F18: Mandatory | G18: Not applicable | J18: =EXACT(G18,'Vh5205_C-81'!G18) -> TRUE
A19: 16 | B19: Test info-->Test parameters--> | C19: Test force | E19: kN | F19: Optional | J19: =EXACT(G19,'Vh5205_C-81'!G19) -> TRUE
A20: 17 | B20: Test info-->Test parameters--> | C20: Preload (Part of the test force) | E20: kN | F20: Mandatory | G20: 0,2 kN (20.4 kg) | H20: * | J20: =EXACT(G20,'Vh5205_C-81'!G20) -> TRUE
A21: 18 | B21: Test info-->Test parameters--> | C21: Other additional information (e.g. if constant stress) | F21: Optional | J21: =EXACT(G21,'Vh5205_C-81'!G21) -> TRUE
A22: 19 | B22: Test info-->Related research outcome--> | C22: Related article(s) available? | F22: Optional | G22: No | H22: * | J22: =EXACT(G22,'Vh5205_C-81'!G22) -> TRUE
A23: 20 | B23: Test info-->Related research outcome--> | C23: DOI Article 1 | F23: Optional | J23: =EXACT(G23,'Vh5205_C-81'!G23) -> TRUE
A24: 21 | B24: Test info-->Related research outcome--> | C24: Short description of content article 1 | F24: Optional | J24: =EXACT(G24,'Vh5205_C-81'!G24) -> TRUE
A25: 22 | B25: Test info-->Related research outcome--> | C25: DOI Article 2 | F25: Optional | J25: =EXACT(G25,'Vh5205_C-81'!G25) -> TRUE
A26: 23 | B26: Test info-->Related research outcome--> | C26: Short description of content article 2 | F26: Optional | J26: =EXACT(G26,'Vh5205_C-81'!G26) -> TRUE
A27: 24 | B27: Test info-->Related research outcome--> | C27: DOI Article n | F27: Optional | J27: =EXACT(G27,'Vh5205_C-81'!G27) -> TRUE
A28: 25 | B28: Test info-->Related research outcome--> | C28: Short description of content article n | F28: Optional | J28: =EXACT(G28,'Vh5205_C-81'!G28) -> TRUE
A29: 26 | B29: Material related-->History and condition of the material--> | C29: (Digital) Material Identifier | F29: Mandatory | G29: CMSX-6 | H29: * | J29: =EXACT(G29,'Vh5205_C-81'!G29) -> TRUE
A30: 27 | B30: Material related-->History and condition of the material-->As-manufactured material--> | C30: Information on phase equilibrium | F30: Optional | J30: =EXACT(G30,'Vh5205_C-81'!G30) -> TRUE
A31: 28 | B31: Material related-->History and condition of the material-->As-manufactured material--> | C31: Type of as-manufactured material (Cast / Ingot / Extrusion rod / …) | F31: Mandatory | G31: Ingot | H31: * | J31: =EXACT(G31,'Vh5205_C-81'!G31) -> TRUE
A32: 29 | B32: Material related-->History and condition of the material-->As-manufactured material--> | C32: Description of the as-manufactured material (geometry and dimensions) | F32: Mandatory | G32: Ingot with 4" Diameter | H32: * | J32: =EXACT(G32,'Vh5205_C-81'!G32) -> TRUE
A33: 30 | B33: Material related-->History and condition of the material-->As-manufactured material--> | C33: Description of the manufacturing process - as-manufactured material | F33: Optional | G33: Vacuum Induction Refined | H33: * | J33: =EXACT(G33,'Vh5205_C-81'!G33) -> TRUE
A34: 31 | B34: Material related-->History and condition of the material-->As-manufactured material--> | C34: Casting temperature | E34: °C | F34: Optional | J34: =EXACT(G34,'Vh5205_C-81'!G34) -> TRUE
A35: 32 | B35: Material related-->History and condition of the material-->As-manufactured material--> | C35: Casting speed | F35: Optional | J35: =EXACT(G35,'Vh5205_C-81'!G35) -> TRUE
A36: 33 | B36: Material related-->History and condition of the material-->As-manufactured material--> | C36: Single or polycrystal solidified | F36: Mandatory | G36: Single Crystal | H36: * | J36: =EXACT(G36,'Vh5205_C-81'!G36) -> TRUE
A37: 34 | B37: Material related-->History and condition of the material-->As-manufactured material--> | C37: Condition | F37: Mandatory | G37: Heat Treated | H37: * | J37: =EXACT(G37,'Vh5205_C-81'!G37) -> TRUE
A38: 35 | B38: Material related-->History and condition of the material-->As-tested material--> | C38: Supplier | F38: Mandatory | G38: PCC Airfoils, Inc. Minerva, Ohio. | H38: * | J38: =EXACT(G38,'Vh5205_C-81'!G38) -> TRUE
A39: 36 | B39: Material related-->History and condition of the material-->As-tested material--> | C39: Description of the as-tested material (geometry and dimensions) - The test piece is manufactured from the tested material. | F39: Mandatory | G39: Single Crystal Investment Cast See image file "Test-piece-location.pdf" For details see DOI: 10.7449/1980/Superalloys_1980_205_214, and DOI: 10.7449/1984/Superalloys_1984_167_176 | H39: * | J39: =EXACT(G39,'Vh5205_C-81'!G39) -> TRUE
A40: 37 | B40: Material related-->History and condition of the material-->As-tested material--> | C40: Description of the manufacturing process - as-tested material | F40: Mandatory | G40: Single Crystal Investment Casting from a Vacuum Induction Refined Ingot and subsequent Heat Treatment (annealed and aged). | H40: * | J40: =EXACT(G40,'Vh5205_C-81'!G40) -> TRUE
...

Sheet Vh5205_C-98
F1: Mandatory
F2: Optional
A3: ROW | B3: CATEGORIZATION | C3: ENTRY | D3: SYMBOL | E3: UNIT | F3: REQUIREMENT | H3: * Information common to all tests
A4: 1 | B4: Test info-->Test job details--> | C4: Date of test start | F4: Mandatory | G4: 45069.385 | J4: =EXACT(G4,'Vh5205_C-91'!G4) -> FALSE
A5: 2 | B5: Test info-->Test job details--> | C5: Data of test end | F5: Mandatory | G5: 45089.552 | J5: =EXACT(G5,'Vh5205_C-91'!G5) -> FALSE
A6: 3 | B6: Test info-->Test job details--> | C6: Test ID | F6: Mandatory | G6: Vh5205_C-98 | J6: =EXACT(G6,'Vh5205_C-91'!G6) -> FALSE
A7: 4 | B7: Test info-->Test job details--> | C7: Project | F7: Optional | G7: Vh 5205 | H7: * | J7: =EXACT(G7,'Vh5205_C-91'!G7) -> TRUE
A8: 5 | B8: Test info-->Test job details--> | C8: Test order | F8: Optional | G8: Not applicable | H8: * | J8: =EXACT(G8,'Vh5205_C-91'!G8) -> TRUE
A9: 6 | B9: Test info-->Test parameters--> | C9: Was the test performed according to a test standard? | F9: Mandatory | G9: Yes | H9: * | J9: =EXACT(G9,'Vh5205_C-91'!G9) -> TRUE
A10: 7 | B10: Test info-->Test parameters--> | C10: Test standard | F10: Mandatory | G10: DIN EN ISO 204:2019-4 | H10: * | J10: =EXACT(G10,'Vh5205_C-91'!G10) -> TRUE
A11: 8 | B11: Test info-->Test parameters--> | C11: Specified temperature | D11: T | E11: °C | F11: Mandatory | G11: 980 °C | H11: * | J11: =EXACT(G11,'Vh5205_C-91'!G11) -> TRUE
A12: 9 | B12: Test info-->Test parameters--> | C12: Type of loading | F12: Mandatory | G12: Tension | H12: * | J12: =EXACT(G12,'Vh5205_C-91'!G12) -> TRUE
A13: 10 | B13: Test info-->Test parameters--> | C13: Load control type | F13: Mandatory | G13: Constant force | H13: * | J13: =EXACT(G13,'Vh5205_C-91'!G13) -> TRUE
A14: 11 | B14: Test info-->Test parameters--> | C14: Initial stress | D14: Ro | E14: MPa | F14: Mandatory | G14: 170 | J14: =EXACT(G14,'Vh5205_C-91'!G14) -> TRUE
A15: 12 | B15: Test info-->Test parameters--> | C15: Test type | F15: Mandatory | G15: Uninterrupted creep tests with continuous monitoring of extension | H15: * | J15: =EXACT(G15,'Vh5205_C-91'!G15) -> TRUE
A16: 13 | B16: Test info-->Test parameters--> | C16: End of test criterium | F16: Mandatory | G16: Test piece break | J16: =EXACT(G16,'Vh5205_C-91'!G16) -> TRUE
A17: 14 | B17: Test info-->Test parameters--> | C17: End of test criterium - value (if not test piece break) | F17: Mandatory | G17: Not applicable | J17: =EXACT(G17,'Vh5205_C-91'!G17) -> TRUE
A18: 15 | B18: Test info-->Test parameters--> | C18: Interruption course | F18: Mandatory | G18: Not applicable | J18: =EXACT(G18,'Vh5205_C-91'!G18) -> TRUE
A19: 16 | B19: Test info-->Test parameters--> | C19: Test force | E19: kN | F19: Optional | J19: =EXACT(G19,'Vh5205_C-91'!G19) -> TRUE
A20: 17 | B20: Test info-->Test parameters--> | C20: Preload (Part of the test force) | E20: kN | F20: Mandatory | G20: 0,2 kN (20.4 kg) | H20: * | J20: =EXACT(G20,'Vh5205_C-91'!G20) -> TRUE
A21: 18 | B21: Test info-->Test parameters--> | C21: Other additional information (e.g. if constant stress) | F21: Optional | J21: =EXACT(G21,'Vh5205_C-91'!G21) -> TRUE
A22: 19 | B22: Test info-->Related research outcome--> | C22: Related article(s) available? | F22: Optional | G22: No | H22: * | J22: =EXACT(G22,'Vh5205_C-91'!G22) -> TRUE
A23: 20 | B23: Test info-->Related research outcome--> | C23: DOI Article 1 | F23: Optional | J23: =EXACT(G23,'Vh5205_C-91'!G23) -> TRUE
A24: 21 | B24: Test info-->Related research outcome--> | C24: Short description of content article 1 | F24: Optional | J24: =EXACT(G24,'Vh5205_C-91'!G24) -> TRUE
A25: 22 | B25: Test info-->Related research outcome--> | C25: DOI Article 2 | F25: Optional | J25: =EXACT(G25,'Vh5205_C-91'!G25) -> TRUE
A26: 23 | B26: Test info-->Related research outcome--> | C26: Short description of content article 2 | F26: Optional | J26: =EXACT(G26,'Vh5205_C-91'!G26) -> TRUE
A27: 24 | B27: Test info-->Related research outcome--> | C27: DOI Article n | F27: Optional | J27: =EXACT(G27,'Vh5205_C-91'!G27) -> TRUE
A28: 25 | B28: Test info-->Related research outcome--> | C28: Short description of content article n | F28: Optional | J28: =EXACT(G28,'Vh5205_C-91'!G28) -> TRUE
A29: 26 | B29: Material related-->History and condition of the material--> | C29: (Digital) Material Identifier | F29: Mandatory | G29: CMSX-6 | H29: * | J29: =EXACT(G29,'Vh5205_C-91'!G29) -> TRUE
A30: 27 | B30: Material related-->History and condition of the material-->As-manufactured material--> | C30: Information on phase equilibrium | F30: Optional | J30: =EXACT(G30,'Vh5205_C-91'!G30) -> TRUE
A31: 28 | B31: Material related-->History and condition of the material-->As-manufactured material--> | C31: Type of as-manufactured material (Cast / Ingot / Extrusion rod / …) | F31: Mandatory | G31: Ingot | H31: * | J31: =EXACT(G31,'Vh5205_C-91'!G31) -> TRUE
A32: 29 | B32: Material related-->History and condition of the material-->As-manufactured material--> | C32: Description of the as-manufactured material (geometry and dimensions) | F32: Mandatory | G32: Ingot with 4" Diameter | H32: * | J32: =EXACT(G32,'Vh5205_C-91'!G32) -> TRUE
A33: 30 | B33: Material related-->History and condition of the material-->As-manufactured material--> | C33: Description of the manufacturing process - as-manufactured material | F33: Optional | G33: Vacuum Induction Refined | H33: * | J33: =EXACT(G33,'Vh5205_C-91'!G33) -> TRUE
A34: 31 | B34: Material related-->History and condition of the material-->As-manufactured material--> | C34: Casting temperature | E34: °C | F34: Optional | J34: =EXACT(G34,'Vh5205_C-91'!G34) -> TRUE
A35: 32 | B35: Material related-->History and condition of the material-->As-manufactured material--> | C35: Casting speed | F35: Optional | J35: =EXACT(G35,'Vh5205_C-91'!G35) -> TRUE
A36: 33 | B36: Material related-->History and condition of the material-->As-manufactured material--> | C36: Single or polycrystal solidified | F36: Mandatory | G36: Single Crystal | H36: * | J36: =EXACT(G36,'Vh5205_C-91'!G36) -> TRUE
A37: 34 | B37: Material related-->History and condition of the material-->As-manufactured material--> | C37: Condition | F37: Mandatory | G37: Heat Treated | H37: * | J37: =EXACT(G37,'Vh5205_C-91'!G37) -> TRUE
A38: 35 | B38: Material related-->History and condition of the material-->As-tested material--> | C38: Supplier | F38: Mandatory | G38: PCC Airfoils, Inc. Minerva, Ohio. | H38: * | J38: =EXACT(G38,'Vh5205_C-91'!G38) -> TRUE
A39: 36 | B39: Material related-->History and condition of the material-->As-tested material--> | C39: Description of the as-tested material (geometry and dimensions) - The test piece is manufactured from the tested material. | F39: Mandatory | G39: Single Crystal Investment Cast See image file "Test-piece-location.pdf" For details see DOI: 10.7449/1980/Superalloys_1980_205_214, and DOI: 10.7449/1984/Superalloys_1984_167_176 | H39: * | J39: =EXACT(G39,'Vh5205_C-91'!G39) -> TRUE
A40: 37 | B40: Material related-->History and condition of the material-->As-tested material--> | C40: Description of the manufacturing process - as-tested material | F40: Mandatory | G40: Single Crystal Investment Casting from a Vacuum Induction Refined Ingot and subsequent Heat Treatment (annealed and aged). | H40: * | J40: =EXACT(G40,'Vh5205_C-91'!G40) -> TRUE
...

Sheet Vh5205_C-82
F1: Mandatory
F2: Optional
A3: ROW | B3: CATEGORIZATION | C3: ENTRY | D3: SYMBOL | E3: UNIT | F3: REQUIREMENT | H3: * Information common to all tests
A4: 1 | B4: Test info-->Test job details--> | C4: Date of test start | F4: Mandatory | G4: 44998.412 | J4: =EXACT(G4,'Vh5205_C-98'!G4) -> FALSE
A5: 2 | B5: Test info-->Test job details--> | C5: Data of test end | F5: Mandatory | G5: 45005.912 | J5: =EXACT(G5,'Vh5205_C-98'!G5) -> FALSE
A6: 3 | B6: Test info-->Test job details--> | C6: Test ID | F6: Mandatory | G6: Vh5205_C-82 | J6: =EXACT(G6,'Vh5205_C-98'!G6) -> FALSE
A7: 4 | B7: Test info-->Test job details--> | C7: Project | F7: Optional | G7: Vh 5205 | H7: * | J7: =EXACT(G7,'Vh5205_C-98'!G7) -> TRUE
A8: 5 | B8: Test info-->Test job details--> | C8: Test order | F8: Optional | G8: Not applicable | H8: * | J8: =EXACT(G8,'Vh5205_C-98'!G8) -> TRUE
A9: 6 | B9: Test info-->Test parameters--> | C9: Was the test performed according to a test standard? | F9: Mandatory | G9: Yes | H9: * | J9: =EXACT(G9,'Vh5205_C-98'!G9) -> TRUE
A10: 7 | B10: Test info-->Test parameters--> | C10: Test standard | F10: Mandatory | G10: DIN EN ISO 204:2019-4 | H10: * | J10: =EXACT(G10,'Vh5205_C-98'!G10) -> TRUE
A11: 8 | B11: Test info-->Test parameters--> | C11: Specified temperature | D11: T | E11: °C | F11: Mandatory | G11: 980 °C | H11: * | J11: =EXACT(G11,'Vh5205_C-98'!G11) -> TRUE
A12: 9 | B12: Test info-->Test parameters--> | C12: Type of loading | F12: Mandatory | G12: Tension | H12: * | J12: =EXACT(G12,'Vh5205_C-98'!G12) -> TRUE
A13: 10 | B13: Test info-->Test parameters--> | C13: Load control type | F13: Mandatory | G13: Constant force | H13: * | J13: =EXACT(G13,'Vh5205_C-98'!G13) -> TRUE
A14: 11 | B14: Test info-->Test parameters--> | C14: Initial stress | D14: Ro | E14: MPa | F14: Mandatory | G14: 200 | J14: =EXACT(G14,'Vh5205_C-98'!G14) -> FALSE
A15: 12 | B15: Test info-->Test parameters--> | C15: Test type | F15: Mandatory | G15: Uninterrupted creep tests with continuous monitoring of extension | H15: * | J15: =EXACT(G15,'Vh5205_C-98'!G15) -> TRUE
A16: 13 | B16: Test info-->Test parameters--> | C16: End of test criterium | F16: Mandatory | G16: Test piece break | J16: =EXACT(G16,'Vh5205_C-98'!G16) -> TRUE
A17: 14 | B17: Test info-->Test parameters--> | C17: End of test criterium - value (if not test piece break) | F17: Mandatory | G17: Not applicable | J17: =EXACT(G17,'Vh5205_C-98'!G17) -> TRUE
A18: 15 | B18: Test info-->Test parameters--> | C18: Interruption course | F18: Mandatory | G18: Not applicable | J18: =EXACT(G18,'Vh5205_C-98'!G18) -> TRUE
A19: 16 | B19: Test info-->Test parameters--> | C19: Test force | E19: kN | F19: Optional | J19: =EXACT(G19,'Vh5205_C-98'!G19) -> TRUE
A20: 17 | B20: Test info-->Test parameters--> | C20: Preload (Part of the test force) | E20: kN | F20: Mandatory | G20: 0,2 kN (20.4 kg) | H20: * | J20: =EXACT(G20,'Vh5205_C-98'!G20) -> TRUE
A21: 18 | B21: Test info-->Test parameters--> | C21: Other additional information (e.g. if constant stress) | F21: Optional | J21: =EXACT(G21,'Vh5205_C-98'!G21) -> TRUE
A22: 19 | B22: Test info-->Related research outcome--> | C22: Related article(s) available? | F22: Optional | G22: No | H22: * | J22: =EXACT(G22,'Vh5205_C-98'!G22) -> TRUE
A23: 20 | B23: Test info-->Related research outcome--> | C23: DOI Article 1 | F23: Optional | J23: =EXACT(G23,'Vh5205_C-98'!G23) -> TRUE
A24: 21 | B24: Test info-->Related research outcome--> | C24: Short description of content article 1 | F24: Optional | J24: =EXACT(G24,'Vh5205_C-98'!G24) -> TRUE
A25: 22 | B25: Test info-->Related research outcome--> | C25: DOI Article 2 | F25: Optional | J25: =EXACT(G25,'Vh5205_C-98'!G25) -> TRUE
A26: 23 | B26: Test info-->Related research outcome--> | C26: Short description of content article 2 | F26: Optional | J26: =EXACT(G26,'Vh5205_C-98'!G26) -> TRUE
A27: 24 | B27: Test info-->Related research outcome--> | C27: DOI Article n | F27: Optional | J27: =EXACT(G27,'Vh5205_C-98'!G27) -> TRUE
A28: 25 | B28: Test info-->Related research outcome--> | C28: Short description of content article n | F28: Optional | J28: =EXACT(G28,'Vh5205_C-98'!G28) -> TRUE
A29: 26 | B29: Material related-->History and condition of the material--> | C29: (Digital) Material Identifier | F29: Mandatory | G29: CMSX-6 | H29: * | J29: =EXACT(G29,'Vh5205_C-98'!G29) -> TRUE
A30: 27 | B30: Material related-->History and condition of the material-->As-manufactured material--> | C30: Information on phase equilibrium | F30: Optional | J30: =EXACT(G30,'Vh5205_C-98'!G30) -> TRUE
A31: 28 | B31: Material related-->History and condition of the material-->As-manufactured material--> | C31: Type of as-manufactured material (Cast / Ingot / Extrusion rod / …) | F31: Mandatory | G31: Ingot | H31: * | J31: =EXACT(G31,'Vh5205_C-98'!G31) -> TRUE
A32: 29 | B32: Material related-->History and condition of the material-->As-manufactured material--> | C32: Description of the as-manufactured material (geometry and dimensions) | F32: Mandatory | G32: Ingot with 4" Diameter | H32: * | J32: =EXACT(G32,'Vh5205_C-98'!G32) -> TRUE
A33: 30 | B33: Material related-->History and condition of the material-->As-manufactured material--> | C33: Description of the manufacturing process - as-manufactured material | F33: Optional | G33: Vacuum Induction Refined | H33: * | J33: =EXACT(G33,'Vh5205_C-98'!G33) -> TRUE
A34: 31 | B34: Material related-->History and condition of the material-->As-manufactured material--> | C34: Casting temperature | E34: °C | F34: Optional | J34: =EXACT(G34,'Vh5205_C-98'!G34) -> TRUE
A35: 32 | B35: Material related-->History and condition of the material-->As-manufactured material--> | C35: Casting speed | F35: Optional | J35: =EXACT(G35,'Vh5205_C-98'!G35) -> TRUE
A36: 33 | B36: Material related-->History and condition of the material-->As-manufactured material--> | C36: Single or polycrystal solidified | F36: Mandatory | G36: Single Crystal | H36: * | J36: =EXACT(G36,'Vh5205_C-98'!G36) -> TRUE
A37: 34 | B37: Material related-->History and condition of the material-->As-manufactured material--> | C37: Condition | F37: Mandatory | G37: Heat Treated | H37: * | J37: =EXACT(G37,'Vh5205_C-98'!G37) -> TRUE
A38: 35 | B38: Material related-->History and condition of the material-->As-tested material--> | C38: Supplier | F38: Mandatory | G38: PCC Airfoils, Inc. Minerva, Ohio. | H38: * | J38: =EXACT(G38,'Vh5205_C-98'!G38) -> TRUE
A39: 36 | B39: Material related-->History and condition of the material-->As-tested material--> | C39: Description of the as-tested material (geometry and dimensions) - The test piece is manufactured from the tested material. | F39: Mandatory | G39: Single Crystal Investment Cast See image file "Test-piece-location.pdf" For details see DOI: 10.7449/1980/Superalloys_1980_205_214, and DOI: 10.7449/1984/Superalloys_1984_167_176 | H39: * | J39: =EXACT(G39,'Vh5205_C-98'!G39) -> TRUE
A40: 37 | B40: Material related-->History and condition of the material-->As-tested material--> | C40: Description of the manufacturing process - as-tested material | F40: Mandatory | G40: Single Crystal Investment Casting from a Vacuum Induction Refined Ingot and subsequent Heat Treatment (annealed and aged). | H40: * | J40: =EXACT(G40,'Vh5205_C-98'!G40) -> TRUE
...

Sheet Vh5205_C-97
F1: Mandatory
F2: Optional
A3: ROW | B3: CATEGORIZATION | C3: ENTRY | D3: SYMBOL | E3: UNIT | F3: REQUIREMENT | H3: * Information common to all tests
A4: 1 | B4: Test info-->Test job details--> | C4: Date of test start | F4: Mandatory | G4: 45007.365 | J4: =EXACT(G4,'Vh5205_C-82'!G4) -> FALSE
